Workbook

Sheet Formatted
A1: Model | B1: Cascade_Level1_CL | C1: Cascade_Level1_SK | D1: Cascade_Level1_Code | E1: Cascade_Level1_PV | F1: Cascade_Level2_SK | G1: Cascade_Level2_Code | H1: Cascade_Level2_PV | I1: End2End_Level1_Code | J1: End2End_Level1_PV | K1: End2End_Level2_Code | L1: End2End_Level2_PV | M1: Level3_Code | N1: Level3_PV
A2: # | B2: Close-source | C2: AGI | D2: LLM | E2: Agents
A3: Gemini-2.5-flash | B3: =Calculation!B32 -> 0.6098 | C3: =Calculation!C32 -> 0.2701 | D3: =Calculation!D32 -> 0.29663333 | E3: =Calculation!E32 -> 0.32763333 | F3: =Calculation!F32 -> 0.35 | G3: =Calculation!G32 -> 0.31743333 | H3: =Calculation!H32 -> 0.37906667 | I3: =Calculation!I32 -> 0.29453333 | ... N3: =Calculation!N32 -> 0.54893333
A4: GPT-3.5-turbo | B4: =Calculation!B33 -> 0.4715 | C4: =Calculation!C33 -> 0.10583333 | D4: =Calculation!D33 -> 0.1269 | E4: =Calculation!E33 -> 0.48793333 | F4: =Calculation!F33 -> 0.11603333 | G4: =Calculation!G33 -> 0.12973333 | H4: =Calculation!H33 -> 0.5039 | I4: =Calculation!I33 -> 0.13033333 | ... N4: =Calculation!N33 -> 0.4605
A5: GPT-5 | B5: =Calculation!B34 -> 0.64256667 | C5: =Calculation!C34 -> 0.34606667 | D5: =Calculation!D34 -> 0.35093333 | E5: =Calculation!E34 -> 0.4276 | F5: =Calculation!F34 -> 0.35723333 | G5: =Calculation!G34 -> 0.37383333 | H5: =Calculation!H34 -> 0.56833333 | I5: =Calculation!I34 -> 0.3196 | ... N5: =Calculation!N34 -> 0.60863333
A6: # | B6: Open-source | C6: AGI | D6: LLM | E6: Agents
A7: Gemma3-12b | B7: =Calculation!B40 -> 0.62053333 | C7: =Calculation!C40 -> 0.1962 | D7: =Calculation!D40 -> 0.20106667 | E7: =Calculation!E40 -> 0.42566667 | F7: =Calculation!F40 -> 0.21426667 | G7: =Calculation!G40 -> 0.1629 | H7: =Calculation!H40 -> 0.31926667 | I7: =Calculation!I40 -> 0.1608 | ... N7: =Calculation!N40 -> 0.3249
A8: Gemma3-27b | B8: =Calculation!B41 -> 0.63153333 | C8: =Calculation!C41 -> 0.19876667 | D8: =Calculation!D41 -> 0.20513333 | E8: =Calculation!E41 -> 0.41613333 | F8: =Calculation!F41 -> 0.20963333 | G8: =Calculation!G41 -> 0.21736667 | H8: =Calculation!H41 -> 0.4173 | I8: =Calculation!I41 -> 0.25386667 | ... N8: =Calculation!N41 -> 0.43183333
A9: GPT-oss-20b | B9: =Calculation!B42 -> 0.55963333 | C9: =Calculation!C42 -> 0.14883333 | D9: =Calculation!D42 -> 0.2284 | E9: =Calculation!E42 -> 0.4066 | F9: =Calculation!F42 -> 0.17503333 | G9: =Calculation!G42 -> 0.22696667 | H9: =Calculation!H42 -> 0.27363333 | I9: =Calculation!I42 -> 0.2012 | ... N9: =Calculation!N42 -> 0.28033333
A10: Llama3.1-8b | B10: =Calculation!B43 -> 0.0497 | C10: =Calculation!C43 -> 0.0391 | D10: =Calculation!D43 -> 0.079366667 | E10: =Calculation!E43 -> 0.0161 | F10: =Calculation!F43 -> 0.039333333 | G10: =Calculation!G43 -> 0.0876 | H10: =Calculation!H43 -> 0.0499 | I10: =Calculation!I43 -> 0.0385 | ... N10: =Calculation!N43 -> 0
A11: Llama3.3-70b | B11: =Calculation!B44 -> 0.49313333 | C11: =Calculation!C44 -> 0.1774 | D11: =Calculation!D44 -> 0.2426 | E11: =Calculation!E44 -> 0.4377 | F11: =Calculation!F44 -> 0.19846667 | G11: =Calculation!G44 -> 0.27803333 | H11: =Calculation!H44 -> 0.4515 | I11: =Calculation!I44 -> 0.25133333 | ... N11: =Calculation!N44 -> 0.42646667
A12: Phi4-14b | B12: =Calculation!B45 -> 0.44646667 | C12: =Calculation!C45 -> 0.067266667 | D12: =Calculation!D45 -> 0.092866667 | E12: =Calculation!E45 -> 0.11086667 | F12: =Calculation!F45 -> 0.088833333 | G12: =Calculation!G45 -> 0.1267 | H12: =Calculation!H45 -> 0.27186667 | I12: =Calculation!I45 -> 0.28106667 | ... N12: =Calculation!N45 -> 0.41363333
A13: Qwen3-14b | B13: =Calculation!B48 -> 0.51313333 | C13: =Calculation!C48 -> 0.15243333 | D13: =Calculation!D48 -> 0.19103333 | E13: =Calculation!E48 -> 0.28506667 | F13: =Calculation!F48 -> 0.1858 | G13: =Calculation!G48 -> 0.16546667 | H13: =Calculation!H48 -> 0.24463333 | I13: =Calculation!I48 -> 0.14043333 | ... N13: =Calculation!N48 -> 0.2738
A14: Qwen3-30b | B14: =Calculation!B49 -> 0.36523333 | C14: =Calculation!C49 -> 0.14253333 | D14: =Calculation!D49 -> 0.1515 | E14: =Calculation!E49 -> 0.26443333 | F14: =Calculation!F49 -> 0.17066667 | G14: =Calculation!G49 -> 0.22766667 | H14: =Calculation!H49 -> 0.27406667 | I14: =Calculation!I49 -> 0.12223333 | ... N14: =Calculation!N49 -> 0.24113333
A15: # | B15: Open-source | C15: Coding | D15: LLM | E15: Agents
A16: Codellama-13b | B16: - | C16: - | D16: - | E16: - | F16: - | G16: - | H16: - | I16: - | J16: - | K16: - | L16: - | M16: =Calculation!M35 -> 0.083 | N16: =Calculation!N35 -> 0.094066667
A17: Codellama-32b | B17: - | C17: - | D17: - | E17: - | F17: - | G17: - | H17: - | I17: - | J17: - | K17: - | L17: - | M17: =Calculation!M36 -> 0.050766667 | N17: =Calculation!N36 -> 0.0166
A18: Codellama-70b | B18: - | C18: - | D18: - | E18: - | F18: - | G18: - | H18: - | I18: - | J18: - | K18: - | L18: - | M18: =Calculation!M37 -> 0 | N18: =Calculation!N37 -> 0
A19: Deepseek-coder-6.7b | B19: - | C19: - | D19: - | E19: - | F19: - | G19: - | H19: - | I19: - | J19: - | K19: - | L19: - | M19: =Calculation!M38 -> 0.2392 | N19: =Calculation!N38 -> 0.072333333
A20: Deepseek-coder-33b | B20: - | C20: - | D20: - | E20: - | F20: - | G20: - | H20: - | I20: - | J20: - | K20: - | L20: - | M20: =Calculation!M39 -> 0.2137 | N20: =Calculation!N39 -> 0.0085666667
A21: Qwen2.5-coder-14b | B21: - | C21: - | D21: - | E21: - | F21: - | G21: - | H21: - | I21: - | J21: - | K21: - | L21: - | M21: =Calculation!M46 -> 0.2448 | N21: =Calculation!N46 -> 0.23413333
A22: Qwen2.5-coder-32b | B22: - | C22: - | D22: - | E22: - | F22: - | G22: - | H22: - | I22: - | J22: - | K22: - | L22: - | M22: =Calculation!M47 -> 0.43193333 | N22: =Calculation!N47 -> 0.35823333
A23: Average | B23: =Calculation!B50 -> 0.49120303 | C23: =Calculation!C50 -> 0.16768485 | D23: =Calculation!D50 -> 0.19694848 | E23: =Calculation!E50 -> 0.32779394 | F23: =Calculation!F50 -> 0.19139091 | G23: =Calculation!G50 -> 0.21033636 | H23: =Calculation!H50 -> 0.34122424 | I23: =Calculation!I50 -> 0.19944545 | ... N23: =Calculation!N50 -> 0.26633889
Q26: e

Sheet Calculation
B1: Cascade | I1: Direct | Q1: Cascade | X1: Direct | AG1: Cascade | AN1: Direct
B2: 1 | F2: 2 | I2: 1 | K2: 2 | M2: 3 | Q2: 1 | U2: 2 | X2: 1 | Z2: 2 | AB2: 3 | AG2: 1 | AK2: 2 | AN2: 1 | AP2: 2 | AR2: 3
A3: Python | B3: CL | C3: SK | D3: Code | E3: PV | F3: SK | G3: Code | H3: PV | I3: Code | J3: PV | K3: Code | L3: PV | M3: Code | N3: PV | P3: Java | Q3: CL | R3: SK | S3: Code | T3: PV | U3: SK | V3: Code | W3: PV | X3: Code | Y3: PV | Z3: Code | AA3: PV | AB3: Code | AC3: PV | AF3: JavaScript | AG3: CL | AH3: SK | AI3: Code | AJ3: PV | AK3: SK | AL3: Code | AM3: PV | AN3: Code | AO3: PV | AP3: Code | AQ3: PV | AR3: Code | AS3: PV
A4: ='Python Pivot'!B7 -> gemini-2.5-flash | B4: ='Python Pivot'!C7 -> 0.62 | C4: ='Python Pivot'!D7 -> 0.3559 | D4: ='Python Pivot'!E7 -> 0.3781 | E4: ='Python Pivot'!F7 -> 0.3233 | F4: ='Python Pivot'!H7 -> 0.3592 | G4: ='Python Pivot'!I7 -> 0.3947 | H4: ='Python Pivot'!J7 -> 0.3086 | I4: ='Python Pivot'!M7 -> 0.4426 | J4: ='Python Pivot'!N7 -> 0.2981 | K4: ='Python Pivot'!Q7 -> 0.433 | L4: ='Python Pivot'!R7 -> 0.3657 | M4: ='Python Pivot'!U7 -> 0.5723 | N4: ='Python Pivot'!V7 -> 0.5056 | P4: ='JavaScript Pivot'!B7 -> gemini-2.5-flash | Q4: ='JavaScript Pivot'!C7 -> 0.6047 | R4: ='JavaScript Pivot'!D7 -> 0.2272 | S4: ='JavaScript Pivot'!E7 -> 0.2559 | T4: ='JavaScript Pivot'!F7 -> 0.3298 | U4: ='JavaScript Pivot'!H7 -> 0.3454 | V4: ='JavaScript Pivot'!I7 -> 0.2788 | W4: ='JavaScript Pivot'!J7 -> 0.4143 | X4: ='JavaScript Pivot'!M7 -> 0.2205 | Y4: ='JavaScript Pivot'!N7 -> 0.283 | Z4: ='JavaScript Pivot'!Q7 -> 0.3344 | AA4: ='JavaScript Pivot'!R7 -> 0.3897 | AB4: ='JavaScript Pivot'!U7 -> 0.5448 | AC4: ='JavaScript Pivot'!V7 -> 0.5706 | AF4: gemini-2.5-flash | AG4: 0.6047 | AH4: 0.2272 | AI4: 0.2559 | AJ4: 0.3298 | AK4: 0.3454 | AL4: 0.2788 | AM4: 0.4143 | AN4: 0.2205 | AO4: 0.283 | AP4: 0.3344 | AQ4: 0.3897 | AR4: 0.5448 | AS4: 0.5706
A5: ='Python Pivot'!B8 -> gpt-3.5-turbo | B5: ='Python Pivot'!C8 -> 0.4465 | C5: ='Python Pivot'!D8 -> 0.1093 | D5: ='Python Pivot'!E8 -> 0.1197 | E5: ='Python Pivot'!F8 -> 0.4574 | F5: ='Python Pivot'!H8 -> 0.1335 | G5: ='Python Pivot'!I8 -> 0.1312 | H5: ='Python Pivot'!J8 -> 0.4741 | I5: ='Python Pivot'!M8 -> 0.1184 | J5: ='Python Pivot'!N8 -> 0.4312 | K5: ='Python Pivot'!Q8 -> 0.1624 | L5: ='Python Pivot'!R8 -> 0.4855 | M5: ='Python Pivot'!U8 -> 0.4066 | N5: ='Python Pivot'!V8 -> 0.4401 | P5: ='JavaScript Pivot'!B8 -> gpt-3.5-turbo | Q5: ='JavaScript Pivot'!C8 -> 0.484 | R5: ='JavaScript Pivot'!D8 -> 0.1041 | S5: ='JavaScript Pivot'!E8 -> 0.1305 | T5: ='JavaScript Pivot'!F8 -> 0.5032 | U5: ='JavaScript Pivot'!H8 -> 0.1073 | V5: ='JavaScript Pivot'!I8 -> 0.129 | W5: ='JavaScript Pivot'!J8 -> 0.5188 | X5: ='JavaScript Pivot'!M8 -> 0.1363 | Y5: ='JavaScript Pivot'!N8 -> 0.4717 | Z5: ='JavaScript Pivot'!Q8 -> 0.2181 | AA5: ='JavaScript Pivot'!R8 -> 0.485 | AB5: ='JavaScript Pivot'!U8 -> 0.4534 | AC5: ='JavaScript Pivot'!V8 -> 0.4707 | AF5: gpt-3.5-turbo | AG5: 0.484 | AH5: 0.1041 | AI5: 0.1305 | AJ5: 0.5032 | AK5: 0.1073 | AL5: 0.129 | AM5: 0.5188 | AN5: 0.1363 | AO5: 0.4717 | AP5: 0.2181 | AQ5: 0.485 | AR5: 0.4534 | AS5: 0.4707
A6: ='Python Pivot'!B9 -> gpt-5 | B6: ='Python Pivot'!C9 -> 0.6351 | C6: ='Python Pivot'!D9 -> 0.417 | D6: ='Python Pivot'!E9 -> 0.4226 | E6: ='Python Pivot'!F9 -> 0.367 | F6: ='Python Pivot'!H9 -> 0.4409 | G6: ='Python Pivot'!I9 -> 0.4533 | H6: ='Python Pivot'!J9 -> 0.5416 | I6: ='Python Pivot'!M9 -> 0.434 | J6: ='Python Pivot'!N9 -> 0.4239 | K6: ='Python Pivot'!Q9 -> 0.4583 | L6: ='Python Pivot'!R9 -> 0.4922 | M6: ='Python Pivot'!U9 -> 0.5877 | N6: ='Python Pivot'!V9 -> 0.6509 | P6: ='JavaScript Pivot'!B9 -> gpt-5 | Q6: ='JavaScript Pivot'!C9 -> 0.6463 | R6: ='JavaScript Pivot'!D9 -> 0.3106 | S6: ='JavaScript Pivot'!E9 -> 0.3151 | T6: ='JavaScript Pivot'!F9 -> 0.4579 | U6: ='JavaScript Pivot'!H9 -> 0.3154 | V6: ='JavaScript Pivot'!I9 -> 0.3341 | W6: ='JavaScript Pivot'!J9 -> 0.5817 | X6: ='JavaScript Pivot'!M9 -> 0.2624 | Y6: ='JavaScript Pivot'!N9 -> 0.4306 | Z6: ='JavaScript Pivot'!Q9 -> 0.3498 | AA6: ='JavaScript Pivot'!R9 -> 0.5412 | AB6: ='JavaScript Pivot'!U9 -> 0.5577 | AC6: ='JavaScript Pivot'!V9 -> 0.5875 | AF6: gpt-5 | AG6: 0.6463 | AH6: 0.3106 | AI6: 0.3151 | AJ6: 0.4579 | AK6: 0.3154 | AL6: 0.3341 | AM6: 0.5817 | AN6: 0.2624 | AO6: 0.4306 | AP6: 0.3498 | AQ6: 0.5412 | AR6: 0.5577 | AS6: 0.5875
A7: ='Python Pivot'!B10 -> codellama-13b | B7: ='Python Pivot'!C10 -> 0 | C7: ='Python Pivot'!D10 -> 0 | D7: ='Python Pivot'!E10 -> 0 | E7: ='Python Pivot'!F10 -> 0 | F7: ='Python Pivot'!H10 -> 0 | G7: ='Python Pivot'!I10 -> 0 | H7: ='Python Pivot'!J10 -> 0 | I7: ='Python Pivot'!M10 -> 0 | J7: ='Python Pivot'!N10 -> 0 | K7: ='Python Pivot'!Q10 -> 0 | L7: ='Python Pivot'!R10 -> 0 | M7: ='Python Pivot'!U10 -> 0.0278 | N7: ='Python Pivot'!V10 -> 0.0392 | P7: ='JavaScript Pivot'!B10 -> codellama-13b | Q7: ='JavaScript Pivot'!C10 -> 0 | R7: ='JavaScript Pivot'!D10 -> 0 | S7: ='JavaScript Pivot'!E10 -> 0 | T7: ='JavaScript Pivot'!F10 -> 0 | U7: ='JavaScript Pivot'!H10 -> 0 | V7: ='JavaScript Pivot'!I10 -> 0 | W7: ='JavaScript Pivot'!J10 -> 0 | X7: ='JavaScript Pivot'!M10 -> 0 | Y7: ='JavaScript Pivot'!N10 -> 0 | Z7: ='JavaScript Pivot'!Q10 -> 0 | AA7: ='JavaScript Pivot'!R10 -> 0 | AB7: ='JavaScript Pivot'!U10 -> 0.1106 | AC7: ='JavaScript Pivot'!V10 -> 0.1215 | AF7: codellama-13b | AR7: 0.1106 | AS7: 0.1215
A8: ='Python Pivot'!B11 -> codellama-34b | B8: ='Python Pivot'!C11 -> 0 | C8: ='Python Pivot'!D11 -> 0 | D8: ='Python Pivot'!E11 -> 0 | E8: ='Python Pivot'!F11 -> 0 | F8: ='Python Pivot'!H11 -> 0 | G8: ='Python Pivot'!I11 -> 0 | H8: ='Python Pivot'!J11 -> 0 | I8: ='Python Pivot'!M11 -> 0 | J8: ='Python Pivot'!N11 -> 0 | K8: ='Python Pivot'!Q11 -> 0 | L8: ='Python Pivot'!R11 -> 0 | M8: ='Python Pivot'!U11 -> 0.0259 | N8: ='Python Pivot'!V11 -> 0 | P8: ='JavaScript Pivot'!B11 -> codellama-34b | Q8: ='JavaScript Pivot'!C11 -> 0 | R8: ='JavaScript Pivot'!D11 -> 0 | S8: ='JavaScript Pivot'!E11 -> 0 | T8: ='JavaScript Pivot'!F11 -> 0 | U8: ='JavaScript Pivot'!H11 -> 0 | V8: ='JavaScript Pivot'!I11 -> 0 | W8: ='JavaScript Pivot'!J11 -> 0 | X8: ='JavaScript Pivot'!M11 -> 0 | Y8: ='JavaScript Pivot'!N11 -> 0 | Z8: ='JavaScript Pivot'!Q11 -> 0 | AA8: ='JavaScript Pivot'!R11 -> 0 | AB8: ='JavaScript Pivot'!U11 -> 0.0632 | AC8: ='JavaScript Pivot'!V11 -> 0.0249 | AF8: codellama-34b | AR8: 0.0632 | AS8: 0.0249
A9: CodeLlama-70B | P9: CodeLlama-70B | AF9: CodeLlama-70B
A10: ='Python Pivot'!B12 -> deepseek-coder-33b | B10: ='Python Pivot'!C12 -> 0 | C10: ='Python Pivot'!D12 -> 0 | D10: ='Python Pivot'!E12 -> 0 | E10: ='Python Pivot'!F12 -> 0 | F10: ='Python Pivot'!H12 -> 0 | G10: ='Python Pivot'!I12 -> 0 | H10: ='Python Pivot'!J12 -> 0 | I10: ='Python Pivot'!M12 -> 0 | J10: ='Python Pivot'!N12 -> 0 | K10: ='Python Pivot'!Q12 -> 0 | L10: ='Python Pivot'!R12 -> 0 | M10: ='Python Pivot'!U12 -> 0.271 | N10: ='Python Pivot'!V12 -> 0.0436 | P10: ='JavaScript Pivot'!B12 -> deepseek-coder-33b | Q10: ='JavaScript Pivot'!C12 -> 0 | R10: ='JavaScript Pivot'!D12 -> 0 | S10: ='JavaScript Pivot'!E12 -> 0 | T10: ='JavaScript Pivot'!F12 -> 0 | U10: ='JavaScript Pivot'!H12 -> 0 | V10: ='JavaScript Pivot'!I12 -> 0 | W10: ='JavaScript Pivot'!J12 -> 0 | X10: ='JavaScript Pivot'!M12 -> 0 | Y10: ='JavaScript Pivot'!N12 -> 0 | Z10: ='JavaScript Pivot'!Q12 -> 0 | AA10: ='JavaScript Pivot'!R12 -> 0 | AB10: ='JavaScript Pivot'!U12 -> 0.2233 | AC10: ='JavaScript Pivot'!V12 -> 0.0867 | AF10: deepseek-coder-33b | AR10: 0.2233 | AS10: 0.0867
A11: ='Python Pivot'!B13 -> deepseek-coder-6.7b | B11: ='Python Pivot'!C13 -> 0 | C11: ='Python Pivot'!D13 -> 0 | D11: ='Python Pivot'!E13 -> 0 | E11: ='Python Pivot'!F13 -> 0 | F11: ='Python Pivot'!H13 -> 0 | G11: ='Python Pivot'!I13 -> 0 | H11: ='Python Pivot'!J13 -> 0 | I11: ='Python Pivot'!M13 -> 0 | J11: ='Python Pivot'!N13 -> 0 | K11: ='Python Pivot'!Q13 -> 0 | L11: ='Python Pivot'!R13 -> 0 | M11: ='Python Pivot'!U13 -> 0.1381 | N11: ='Python Pivot'!V13 -> 0.0039 | P11: ='JavaScript Pivot'!B13 -> deepseek-coder-6.7b | Q11: ='JavaScript Pivot'!C13 -> 0 | R11: ='JavaScript Pivot'!D13 -> 0 | S11: ='JavaScript Pivot'!E13 -> 0 | T11: ='JavaScript Pivot'!F13 -> 0 | U11: ='JavaScript Pivot'!H13 -> 0 | V11: ='JavaScript Pivot'!I13 -> 0 | W11: ='JavaScript Pivot'!J13 -> 0 | X11: ='JavaScript Pivot'!M13 -> 0 | Y11: ='JavaScript Pivot'!N13 -> 0 | Z11: ='JavaScript Pivot'!Q13 -> 0 | AA11: ='JavaScript Pivot'!R13 -> 0 | AB11: ='JavaScript Pivot'!U13 -> 0.2515 | AC11: ='JavaScript Pivot'!V13 -> 0.0109 | AF11: deepseek-coder-6.7b | AR11: 0.2515 | AS11: 0.0109
A12: ='Python Pivot'!B14 -> gemma3-12b | B12: ='Python Pivot'!C14 -> 0.6186 | C12: ='Python Pivot'!D14 -> 0.1858 | D12: ='Python Pivot'!E14 -> 0.2086 | E12: ='Python Pivot'!F14 -> 0.3262 | F12: ='Python Pivot'!H14 -> 0.1902 | G12: ='Python Pivot'!I14 -> 0.1179 | H12: ='Python Pivot'!J14 -> 0.1906 | I12: ='Python Pivot'!M14 -> 0.1468 | J12: ='Python Pivot'!N14 -> 0.1674 | K12: ='Python Pivot'!Q14 -> 0.2087 | L12: ='Python Pivot'!R14 -> 0.4221 | M12: ='Python Pivot'!U14 -> 0.3606 | N12: ='Python Pivot'!V14 -> 0.3393 | P12: ='JavaScript Pivot'!B14 -> gemma3-12b | Q12: ='JavaScript Pivot'!C14 -> 0.6215 | R12: ='JavaScript Pivot'!D14 -> 0.2014 | S12: ='JavaScript Pivot'!E14 -> 0.1973 | T12: ='JavaScript Pivot'!F14 -> 0.4754 | U12: ='JavaScript Pivot'!H14 -> 0.2263 | V12: ='JavaScript Pivot'!I14 -> 0.1854 | W12: ='JavaScript Pivot'!J14 -> 0.3836 | X12: ='JavaScript Pivot'!M14 -> 0.1678 | Y12: ='JavaScript Pivot'!N14 -> 0.3811 | Z12: ='JavaScript Pivot'!Q14 -> 0.0975 | AA12: ='JavaScript Pivot'!R14 -> 0.1938 | AB12: ='JavaScript Pivot'!U14 -> 0.3641 | AC12: ='JavaScript Pivot'!V14 -> 0.3177 | AF12: gemma3-12b | AG12: 0.6215 | AH12: 0.2014 | AI12: 0.1973 | AJ12: 0.4754 | AK12: 0.2263 | AL12: 0.1854 | AM12: 0.3836 | AN12: 0.1678 | AO12: 0.3811 | AP12: 0.0975 | AQ12: 0.1938 | AR12: 0.3641 | AS12: 0.3177
A13: ='Python Pivot'!B15 -> gemma3-27b | B13: ='Python Pivot'!C15 -> 0.5896 | C13: ='Python Pivot'!D15 -> 0.1905 | D13: ='Python Pivot'!E15 -> 0.145 | E13: ='Python Pivot'!F15 -> 0.1488 | F13: ='Python Pivot'!H15 -> 0.1943 | G13: ='Python Pivot'!I15 -> 0.1637 | H13: ='Python Pivot'!J15 -> 0.2421 | I13: ='Python Pivot'!M15 -> 0.316 | J13: ='Python Pivot'!N15 -> 0.4257 | K13: ='Python Pivot'!Q15 -> 0.3398 | L13: ='Python Pivot'!R15 -> 0.4399 | M13: ='Python Pivot'!U15 -> 0.4747 | N13: ='Python Pivot'!V15 -> 0.4811 | P13: ='JavaScript Pivot'!B15 -> gemma3-27b | Q13: ='JavaScript Pivot'!C15 -> 0.6525 | R13: ='JavaScript Pivot'!D15 -> 0.2029 | S13: ='JavaScript Pivot'!E15 -> 0.2352 | T13: ='JavaScript Pivot'!F15 -> 0.5498 | U13: ='JavaScript Pivot'!H15 -> 0.2173 | V13: ='JavaScript Pivot'!I15 -> 0.2442 | W13: ='JavaScript Pivot'!J15 -> 0.5049 | X13: ='JavaScript Pivot'!M15 -> 0.2228 | Y13: ='JavaScript Pivot'!N15 -> 0.5042 | Z13: ='JavaScript Pivot'!Q15 -> 0.2499 | AA13: ='JavaScript Pivot'!R15 -> 0.4669 | AB13: ='JavaScript Pivot'!U15 -> 0.517 | AC13: ='JavaScript Pivot'!V15 -> 0.4072 | AF13: gemma3-27b | AG13: 0.6525 | AH13: 0.2029 | AI13: 0.2352 | AJ13: 0.5498 | AK13: 0.2173 | AL13: 0.2442 | AM13: 0.5049 | AN13: 0.2228 | AO13: 0.5042 | AP13: 0.2499 | AQ13: 0.4669 | AR13: 0.517 | AS13: 0.4072
A14: ='Python Pivot'!B16 -> gpt-oss-20b | B14: ='Python Pivot'!C16 -> 0.5327 | C14: ='Python Pivot'!D16 -> 0.1325 | D14: ='Python Pivot'!E16 -> 0.2348 | E14: ='Python Pivot'!F16 -> 0.2304 | F14: ='Python Pivot'!H16 -> 0.1267 | G14: ='Python Pivot'!I16 -> 0.3067 | H14: ='Python Pivot'!J16 -> 0.2937 | I14: ='Python Pivot'!M16 -> 0.2538 | J14: ='Python Pivot'!N16 -> 0.3055 | K14: ='Python Pivot'!Q16 -> 0.3062 | L14: ='Python Pivot'!R16 -> 0.3723 | M14: ='Python Pivot'!U16 -> 0.4738 | N14: ='Python Pivot'!V16 -> 0.3808 | P14: ='JavaScript Pivot'!B16 -> gpt-oss-20b | Q14: ='JavaScript Pivot'!C16 -> 0.5731 | R14: ='JavaScript Pivot'!D16 -> 0.157 | S14: ='JavaScript Pivot'!E16 -> 0.2252 | T14: ='JavaScript Pivot'!F16 -> 0.4947 | U14: ='JavaScript Pivot'!H16 -> 0.1992 | V14: ='JavaScript Pivot'!I16 -> 0.1871 | W14: ='JavaScript Pivot'!J16 -> 0.2636 | X14: ='JavaScript Pivot'!M16 -> 0.1749 | Y14: ='JavaScript Pivot'!N16 -> 0.2462 | Z14: ='JavaScript Pivot'!Q16 -> 0.2697 | AA14: ='JavaScript Pivot'!R16 -> 0.3058 | AB14: ='JavaScript Pivot'!U16 -> 0.4085 | AC14: ='JavaScript Pivot'!V16 -> 0.2301 | AF14: gpt-oss-20b | AG14: 0.5731 | AH14: 0.157 | AI14: 0.2252 | AJ14: 0.4947 | AK14: 0.1992 | AL14: 0.1871 | AM14: 0.2636 | AN14: 0.1749 | AO14: 0.2462 | AP14: 0.2697 | AQ14: 0.3058 | AR14: 0.4085 | AS14: 0.2301
A15: ='Python Pivot'!B17 -> llama3.1-8b | B15: ='Python Pivot'!C17 -> 0.0665 | C15: ='Python Pivot'!D17 -> 0.0365 | D15: ='Python Pivot'!E17 -> 0.0523 | E15: ='Python Pivot'!F17 -> 0.0483 | F15: ='Python Pivot'!H17 -> 0.0488 | G15: ='Python Pivot'!I17 -> 0.0722 | H15: ='Python Pivot'!J17 -> 0.0737 | I15: ='Python Pivot'!M17 -> 0.0197 | J15: ='Python Pivot'!N17 -> 0 | K15: ='Python Pivot'!Q17 -> 0.0211 | L15: ='Python Pivot'!R17 -> 0.0722 | M15: ='Python Pivot'!U17 -> 0.0603 | N15: ='Python Pivot'!V17 -> 0 | P15: ='JavaScript Pivot'!B17 -> llama3.1-8b | Q15: ='JavaScript Pivot'!C17 -> 0.0413 | R15: ='JavaScript Pivot'!D17 -> 0.0404 | S15: ='JavaScript Pivot'!E17 -> 0.0929 | T15: ='JavaScript Pivot'!F17 -> 0 | U15: ='JavaScript Pivot'!H17 -> 0.0346 | V15: ='JavaScript Pivot'!I17 -> 0.0953 | W15: ='JavaScript Pivot'!J17 -> 0.038 | X15: ='JavaScript Pivot'!M17 -> 0.0479 | Y15: ='JavaScript Pivot'!N17 -> 0 | Z15: ='JavaScript Pivot'!Q17 -> 0.1617 | AA15: ='JavaScript Pivot'!R17 -> 0.0111 | AB15: ='JavaScript Pivot'!U17 -> 0.0777 | AC15: ='JavaScript Pivot'!V17 -> 0 | AF15: llama3.1-8b | AG15: 0.0413 | AH15: 0.0404 | AI15: 0.0929 | AJ15: 0 | AK15: 0.0346 | AL15: 0.0953 | AM15: 0.038 | AN15: 0.0479 | AO15: 0 | AP15: 0.1617 | AQ15: 0.0111 | AR15: 0.0777 | AS15: 0
A16: ='Python Pivot'!B18 -> llama3.3-70b | B16: ='Python Pivot'!C18 -> 0.4956 | C16: ='Python Pivot'!D18 -> 0.1648 | D16: ='Python Pivot'!E18 -> 0.2228 | E16: ='Python Pivot'!F18 -> 0.3481 | F16: ='Python Pivot'!H18 -> 0.1752 | G16: ='Python Pivot'!I18 -> 0.2767 | H16: ='Python Pivot'!J18 -> 0.4205 | I16: ='Python Pivot'!M18 -> 0.3432 | J16: ='Python Pivot'!N18 -> 0.5099 | K16: ='Python Pivot'!Q18 -> 0.2928 | L16: ='Python Pivot'!R18 -> 0.4608 | M16: ='Python Pivot'!U18 -> 0.3683 | N16: ='Python Pivot'!V18 -> 0.401 | P16: ='JavaScript Pivot'!B18 -> llama3.3-70b | Q16: ='JavaScript Pivot'!C18 -> 0.4919 | R16: ='JavaScript Pivot'!D18 -> 0.1837 | S16: ='JavaScript Pivot'!E18 -> 0.2525 | T16: ='JavaScript Pivot'!F18 -> 0.4825 | U16: ='JavaScript Pivot'!H18 -> 0.2101 | V16: ='JavaScript Pivot'!I18 -> 0.2787 | W16: ='JavaScript Pivot'!J18 -> 0.467 | X16: ='JavaScript Pivot'!M18 -> 0.2054 | Y16: ='JavaScript Pivot'!N18 -> 0.3593 | Z16: ='JavaScript Pivot'!Q18 -> 0.2497 | AA16: ='JavaScript Pivot'!R18 -> 0.4965 | AB16: ='JavaScript Pivot'!U18 -> 0.4753 | AC16: ='JavaScript Pivot'!V18 -> 0.4392 | AF16: llama3.3-70b | AG16: 0.4919 | AH16: 0.1837 | AI16: 0.2525 | AJ16: 0.4825 | AK16: 0.2101 | AL16: 0.2787 | AM16: 0.467 | AN16: 0.2054 | AO16: 0.3593 | AP16: 0.2497 | AQ16: 0.4965 | AR16: 0.4753 | AS16: 0.4392
A17: ='Python Pivot'!B19 -> phi4-14b | B17: ='Python Pivot'!C19 -> 0.5782 | C17: ='Python Pivot'!D19 -> 0 | D17: ='Python Pivot'!E19 -> 0 | E17: ='Python Pivot'!F19 -> 0 | F17: ='Python Pivot'!H19 -> 0.0291 | G17: ='Python Pivot'!I19 -> 0.0281 | H17: ='Python Pivot'!J19 -> 0.071 | I17: ='Python Pivot'!M19 -> 0.3934 | J17: ='Python Pivot'!N19 -> 0.4334 | K17: ='Python Pivot'!Q19 -> 0.3619 | L17: ='Python Pivot'!R19 -> 0.4564 | M17: ='Python Pivot'!U19 -> 0.5108 | N17: ='Python Pivot'!V19 -> 0.4693 | P17: ='JavaScript Pivot'!B19 -> phi4-14b | Q17: ='JavaScript Pivot'!C19 -> 0.3806 | R17: ='JavaScript Pivot'!D19 -> 0.1009 | S17: ='JavaScript Pivot'!E19 -> 0.1393 | T17: ='JavaScript Pivot'!F19 -> 0.1663 | U17: ='JavaScript Pivot'!H19 -> 0.1187 | V17: ='JavaScript Pivot'!I19 -> 0.176 | W17: ='JavaScript Pivot'!J19 -> 0.3723 | X17: ='JavaScript Pivot'!M19 -> 0.2249 | Y17: ='JavaScript Pivot'!N19 -> 0.3935 | Z17: ='JavaScript Pivot'!Q19 -> 0.2904 | AA17: ='JavaScript Pivot'!R19 -> 0.4363 | AB17: ='JavaScript Pivot'!U19 -> 0.5527 | AC17: ='JavaScript Pivot'!V19 -> 0.3858 | AF17: phi4-14b | AG17: 0.3806 | AH17: 0.1009 | AI17: 0.1393 | AJ17: 0.1663 | AK17: 0.1187 | AL17: 0.176 | AM17: 0.3723 | AN17: 0.2249 | AO17: 0.3935 | AP17: 0.2904 | AQ17: 0.4363 | AR17: 0.5527 | AS17: 0.3858
A18: ='Python Pivot'!B20 -> qwen2.5-coder-14b | B18: ='Python Pivot'!C20 -> 0 | C18: ='Python Pivot'!D20 -> 0 | D18: ='Python Pivot'!E20 -> 0 | E18: ='Python Pivot'!F20 -> 0 | F18: ='Python Pivot'!H20 -> 0 | G18: ='Python Pivot'!I20 -> 0 | H18: ='Python Pivot'!J20 -> 0 | I18: ='Python Pivot'!M20 -> 0 | J18: ='Python Pivot'!N20 -> 0 | K18: ='Python Pivot'!Q20 -> 0 | L18: ='Python Pivot'!R20 -> 0 | M18: ='Python Pivot'!U20 -> 0.021 | N18: ='Python Pivot'!V20 -> 0.0376 | P18: ='JavaScript Pivot'!B20 -> qwen2.5-coder-14b | Q18: ='JavaScript Pivot'!C20 -> 0 | R18: ='JavaScript Pivot'!D20 -> 0 | S18: ='JavaScript Pivot'!E20 -> 0 | T18: ='JavaScript Pivot'!F20 -> 0 | U18: ='JavaScript Pivot'!H20 -> 0 | V18: ='JavaScript Pivot'!I20 -> 0 | W18: ='JavaScript Pivot'!J20 -> 0 | X18: ='JavaScript Pivot'!M20 -> 0 | Y18: ='JavaScript Pivot'!N20 -> 0 | Z18: ='JavaScript Pivot'!Q20 -> 0 | AA18: ='JavaScript Pivot'!R20 -> 0 | AB18: ='JavaScript Pivot'!U20 -> 0.3567 | AC18: ='JavaScript Pivot'!V20 -> 0.3324 | AF18: qwen2.5-coder-14b | AR18: 0.3567 | AS18: 0.3324
A19: ='Python Pivot'!B21 -> qwen2.5-coder-32b | B19: ='Python Pivot'!C21 -> 0 | C19: ='Python Pivot'!D21 -> 0 | D19: ='Python Pivot'!E21 -> 0 | E19: ='Python Pivot'!F21 -> 0 | F19: ='Python Pivot'!H21 -> 0 | G19: ='Python Pivot'!I21 -> 0 | H19: ='Python Pivot'!J21 -> 0 | I19: ='Python Pivot'!M21 -> 0 | J19: ='Python Pivot'!N21 -> 0 | K19: ='Python Pivot'!Q21 -> 0 | L19: ='Python Pivot'!R21 -> 0 | M19: ='Python Pivot'!U21 -> 0.4206 | N19: ='Python Pivot'!V21 -> 0.3059 | P19: ='JavaScript Pivot'!B21 -> qwen2.5-coder-32b | Q19: ='JavaScript Pivot'!C21 -> 0 | R19: ='JavaScript Pivot'!D21 -> 0 | S19: ='JavaScript Pivot'!E21 -> 0 | T19: ='JavaScript Pivot'!F21 -> 0 | U19: ='JavaScript Pivot'!H21 -> 0 | V19: ='JavaScript Pivot'!I21 -> 0 | W19: ='JavaScript Pivot'!J21 -> 0 | X19: ='JavaScript Pivot'!M21 -> 0 | Y19: ='JavaScript Pivot'!N21 -> 0 | Z19: ='JavaScript Pivot'!Q21 -> 0 | AA19: ='JavaScript Pivot'!R21 -> 0 | AB19: ='JavaScript Pivot'!U21 -> 0.4376 | AC19: ='JavaScript Pivot'!V21 -> 0.3844 | AF19: qwen2.5-coder-32b | AR19: 0.4376 | AS19: 0.3844
A20: ='Python Pivot'!B22 -> qwen3-14b | B20: ='Python Pivot'!C22 -> 0.3866 | C20: ='Python Pivot'!D22 -> 0.1039 | D20: ='Python Pivot'!E22 -> 0.1789 | E20: ='Python Pivot'!F22 -> 0.1654 | F20: ='Python Pivot'!H22 -> 0.1704 | G20: ='Python Pivot'!I22 -> 0.201 | H20: ='Python Pivot'!J22 -> 0.2819 | I20: ='Python Pivot'!M22 -> 0.1971 | J20: ='Python Pivot'!N22 -> 0.2602 | K20: ='Python Pivot'!Q22 -> 0.2619 | L20: ='Python Pivot'!R22 -> 0.3938 | M20: ='Python Pivot'!U22 -> 0.4541 | N20: ='Python Pivot'!V22 -> 0.3728 | P20: ='JavaScript Pivot'!B22 -> qwen3-14b | Q20: ='JavaScript Pivot'!C22 -> 0.5764 | R20: ='JavaScript Pivot'!D22 -> 0.1767 | S20: ='JavaScript Pivot'!E22 -> 0.1971 | T20: ='JavaScript Pivot'!F22 -> 0.3449 | U20: ='JavaScript Pivot'!H22 -> 0.1935 | V20: ='JavaScript Pivot'!I22 -> 0.1477 | W20: ='JavaScript Pivot'!J22 -> 0.226 | X20: ='JavaScript Pivot'!M22 -> 0.1121 | Y20: ='JavaScript Pivot'!N22 -> 0.1676 | Z20: ='JavaScript Pivot'!Q22 -> 0.0598 | AA20: ='JavaScript Pivot'!R22 -> 0.1463 | AB20: ='JavaScript Pivot'!U22 -> 0.2843 | AC20: ='JavaScript Pivot'!V22 -> 0.2243 | AF20: qwen3-14b | AG20: 0.5764 | AH20: 0.1767 | AI20: 0.1971 | AJ20: 0.3449 | AK20: 0.1935 | AL20: 0.1477 | AM20: 0.226 | AN20: 0.1121 | AO20: 0.1676 | AP20: 0.0598 | AQ20: 0.1463 | AR20: 0.2843 | AS20: 0.2243
A21: ='Python Pivot'!B23 -> qwen3-30b | B21: ='Python Pivot'!C23 -> 0.3779 | C21: ='Python Pivot'!D23 -> 0.1494 | D21: ='Python Pivot'!E23 -> 0.1763 | E21: ='Python Pivot'!F23 -> 0.1315 | F21: ='Python Pivot'!H23 -> 0.1652 | G21: ='Python Pivot'!I23 -> 0.271 | H21: ='Python Pivot'!J23 -> 0.186 | I21: ='Python Pivot'!M23 -> 0.1971 | J21: ='Python Pivot'!N23 -> 0.1653 | K21: ='Python Pivot'!Q23 -> 0.1827 | L21: ='Python Pivot'!R23 -> 0.1545 | M21: ='Python Pivot'!U23 -> 0.5186 | N21: ='Python Pivot'!V23 -> 0.265 | P21: ='JavaScript Pivot'!B23 -> qwen3-30b | Q21: ='JavaScript Pivot'!C23 -> 0.3589 | R21: ='JavaScript Pivot'!D23 -> 0.1391 | S21: ='JavaScript Pivot'!E23 -> 0.1391 | T21: ='JavaScript Pivot'!F23 -> 0.3309 | U21: ='JavaScript Pivot'!H23 -> 0.1734 | V21: ='JavaScript Pivot'!I23 -> 0.206 | W21: ='JavaScript Pivot'!J23 -> 0.3181 | X21: ='JavaScript Pivot'!M23 -> 0.0848 | Y21: ='JavaScript Pivot'!N23 -> 0.2825 | Z21: ='JavaScript Pivot'!Q23 -> 0.1283 | AA21: ='JavaScript Pivot'!R23 -> 0.2093 | AB21: ='JavaScript Pivot'!U23 -> 0.4322 | AC21: ='JavaScript Pivot'!V23 -> 0.2292 | AF21: qwen3-30b | AG21: 0.3589 | AH21: 0.1391 | AI21: 0.1391 | AJ21: 0.3309 | AK21: 0.1734 | AL21: 0.206 | AM21: 0.3181 | AN21: 0.0848 | AO21: 0.2825 | AP21: 0.1283 | AQ21: 0.2093 | AR21: 0.4322 | AS21: 0.2292
A32: Gemini-2.5-flash | B32: =(B4+Q4+AG4)/3 -> 0.6098 | C32: =(C4+R4+AH4)/3 -> 0.2701 | D32: =(D4+S4+AI4)/3 -> 0.29663333 | E32: =(E4+T4+AJ4)/3 -> 0.32763333 | F32: =(F4+U4+AK4)/3 -> 0.35 | G32: =(G4+V4+AL4)/3 -> 0.31743333 | H32: =(H4+W4+AM4)/3 -> 0.37906667 | I32: =(I4+X4+AN4)/3 -> 0.29453333 | ... N32: =(N4+AC4+AS4)/3 -> 0.54893333
A33: GPT-3.5-turbo | B33: =(B5+Q5+AG5)/3 -> 0.4715 | C33: =(C5+R5+AH5)/3 -> 0.10583333 | D33: =(D5+S5+AI5)/3 -> 0.1269 | E33: =(E5+T5+AJ5)/3 -> 0.48793333 | F33: =(F5+U5+AK5)/3 -> 0.11603333 | G33: =(G5+V5+AL5)/3 -> 0.12973333 | H33: =(H5+W5+AM5)/3 -> 0.5039 | I33: =(I5+X5+AN5)/3 -> 0.13033333 | ... N33: =(N5+AC5+AS5)/3 -> 0.4605
A34: GPT-5 | B34: =(B6+Q6+AG6)/3 -> 0.64256667 | C34: =(C6+R6+AH6)/3 -> 0.34606667 | D34: =(D6+S6+AI6)/3 -> 0.35093333 | E34: =(E6+T6+AJ6)/3 -> 0.4276 | F34: =(F6+U6+AK6)/3 -> 0.35723333 | G34: =(G6+V6+AL6)/3 -> 0.37383333 | H34: =(H6+W6+AM6)/3 -> 0.56833333 | I34: =(I6+X6+AN6)/3 -> 0.3196 | ... N34: =(N6+AC6+AS6)/3 -> 0.60863333
A35: Codellama-13b | B35: =(B7+Q7+AG7)/3 -> 0 | C35: =(C7+R7+AH7)/3 -> 0 | D35: =(D7+S7+AI7)/3 -> 0 | E35: =(E7+T7+AJ7)/3 -> 0 | F35: =(F7+U7+AK7)/3 -> 0 | G35: =(G7+V7+AL7)/3 -> 0 | H35: =(H7+W7+AM7)/3 -> 0 | I35: =(I7+X7+AN7)/3 -> 0 | ... N35: =(N7+AC7+AS7)/3 -> 0.094066667
A36: Codellama-32b | B36: =(B8+Q8+AG8)/3 -> 0 | C36: =(C8+R8+AH8)/3 -> 0 | D36: =(D8+S8+AI8)/3 -> 0 | E36: =(E8+T8+AJ8)/3 -> 0 | F36: =(F8+U8+AK8)/3 -> 0 | G36: =(G8+V8+AL8)/3 -> 0 | H36: =(H8+W8+AM8)/3 -> 0 | I36: =(I8+X8+AN8)/3 -> 0 | ... N36: =(N8+AC8+AS8)/3 -> 0.0166
A37: Codellama-70b | B37: =(B9+Q9+AG9)/3 -> 0 | C37: =(C9+R9+AH9)/3 -> 0 | D37: =(D9+S9+AI9)/3 -> 0 | E37: =(E9+T9+AJ9)/3 -> 0 | F37: =(F9+U9+AK9)/3 -> 0 | G37: =(G9+V9+AL9)/3 -> 0 | H37: =(H9+W9+AM9)/3 -> 0 | I37: =(I9+X9+AN9)/3 -> 0 | ... N37: =(N9+AC9+AS9)/3 -> 0
A38: Deepseek-coder-33b | B38: =(B10+Q10+AG10)/3 -> 0 | C38: =(C10+R10+AH10)/3 -> 0 | D38: =(D10+S10+AI10)/3 -> 0 | E38: =(E10+T10+AJ10)/3 -> 0 | F38: =(F10+U10+AK10)/3 -> 0 | G38: =(G10+V10+AL10)/3 -> 0 | H38: =(H10+W10+AM10)/3 -> 0 | I38: =(I10+X10+AN10)/3 -> 0 | ... N38: =(N10+AC10+AS10)/3 -> 0.072333333
A39: Deepseek-coder-6.7b | B39: =(B11+Q11+AG11)/3 -> 0 | C39: =(C11+R11+AH11)/3 -> 0 | D39: =(D11+S11+AI11)/3 -> 0 | E39: =(E11+T11+AJ11)/3 -> 0 | F39: =(F11+U11+AK11)/3 -> 0 | G39: =(G11+V11+AL11)/3 -> 0 | H39: =(H11+W11+AM11)/3 -> 0 | I39: =(I11+X11+AN11)/3 -> 0 | ... N39: =(N11+AC11+AS11)/3 -> 0.0085666667
A40: Gemma3-12b | B40: =(B12+Q12+AG12)/3 -> 0.62053333 | C40: =(C12+R12+AH12)/3 -> 0.1962 | D40: =(D12+S12+AI12)/3 -> 0.20106667 | E40: =(E12+T12+AJ12)/3 -> 0.42566667 | F40: =(F12+U12+AK12)/3 -> 0.21426667 | G40: =(G12+V12+AL12)/3 -> 0.1629 | H40: =(H12+W12+AM12)/3 -> 0.31926667 | I40: =(I12+X12+AN12)/3 -> 0.1608 | ... N40: =(N12+AC12+AS12)/3 -> 0.3249
A41: Gemma3-27b | B41: =(B13+Q13+AG13)/3 -> 0.63153333 | C41: =(C13+R13+AH13)/3 -> 0.19876667 | D41: =(D13+S13+AI13)/3 -> 0.20513333 | E41: =(E13+T13+AJ13)/3 -> 0.41613333 | F41: =(F13+U13+AK13)/3 -> 0.20963333 | G41: =(G13+V13+AL13)/3 -> 0.21736667 | H41: =(H13+W13+AM13)/3 -> 0.4173 | I41: =(I13+X13+AN13)/3 -> 0.25386667 | ... N41: =(N13+AC13+AS13)/3 -> 0.43183333
A42: GPT-oss-20b | B42: =(B14+Q14+AG14)/3 -> 0.55963333 | C42: =(C14+R14+AH14)/3 -> 0.14883333 | D42: =(D14+S14+AI14)/3 -> 0.2284 | E42: =(E14+T14+AJ14)/3 -> 0.4066 | F42: =(F14+U14+AK14)/3 -> 0.17503333 | G42: =(G14+V14+AL14)/3 -> 0.22696667 | H42: =(H14+W14+AM14)/3 -> 0.27363333 | I42: =(I14+X14+AN14)/3 -> 0.2012 | ... N42: =(N14+AC14+AS14)/3 -> 0.28033333
A43: Llama3.1-8b | B43: =(B15+Q15+AG15)/3 -> 0.0497 | C43: =(C15+R15+AH15)/3 -> 0.0391 | D43: =(D15+S15+AI15)/3 -> 0.079366667 | E43: =(E15+T15+AJ15)/3 -> 0.0161 | F43: =(F15+U15+AK15)/3 -> 0.039333333 | G43: =(G15+V15+AL15)/3 -> 0.0876 | H43: =(H15+W15+AM15)/3 -> 0.0499 | I43: =(I15+X15+AN15)/3 -> 0.0385 | ... N43: =(N15+AC15+AS15)/3 -> 0
... A49: Qwen3-30b | B49: =(B21+Q21+AG21)/3 -> 0.36523333 | C49: =(C21+R21+AH21)/3 -> 0.14253333 | D49: =(D21+S21+AI21)/3 -> 0.1515 | E49: =(E21+T21+AJ21)/3 -> 0.26443333 | F49: =(F21+U21+AK21)/3 -> 0.17066667 | G49: =(G21+V21+AL21)/3 -> 0.22766667 | H49: =(H21+W21+AM21)/3 -> 0.27406667 | I49: =(I21+X21+AN21)/3 -> 0.12223333 | ... N49: =(N21+AC21+AS21)/3 -> 0.24113333
A50: Ave | B50: =AVERAGE(B32:B34,B40:B45,B48:B49) -> 0.49120303 | C50: =AVERAGE(C32:C34,C40:C45,C48:C49) -> 0.16768485 | D50: =AVERAGE(D32:D34,D40:D45,D48:D49) -> 0.19694848 | E50: =AVERAGE(E32:E34,E40:E45,E48:E49) -> 0.32779394 | F50: =AVERAGE(F32:F34,F40:F45,F48:F49) -> 0.19139091 | G50: =AVERAGE(G32:G34,G40:G45,G48:G49) -> 0.21033636 | H50: =AVERAGE(H32:H34,H40:H45,H48:H49) -> 0.34122424 | I50: =AVERAGE(I32:I34,I40:I45,I48:I49) -> 0.19944545 | ... L50: =AVERAGE(L32:L34,L40:L45,L48:L49) -> 0.34785455 | M50: =AVERAGE(M32:M49) -> 0.33172963 | N50: =AVERAGE(N32:N49) -> 0.26633889

Sheet Python Pivot
C3: mode | D3: level | E3: 值
C4: cascade | K4: direct | W4: 平均值项:checklist汇总 | X4: 平均值项:skeleton汇总 | Y4: 平均值项:code汇总 | Z4: 平均值项:parameter汇总
C5: 1 | G5: 2 | K5: 1 | O5: 2 | S5: 3
A6: source | B6: model | C6: 平均值项:checklist | D6: 平均值项:skeleton | E6: 平均值项:code | F6: 平均值项:parameter | G6: 平均值项:checklist | H6: 平均值项:skeleton | I6: 平均值项:code | J6: 平均值项:parameter | K6: 平均值项:checklist | L6: 平均值项:skeleton | M6: 平均值项:code | N6: 平均值项:parameter | O6: 平均值项:checklist | P6: 平均值项:skeleton | Q6: 平均值项:code | R6: 平均值项:parameter | S6: 平均值项:checklist | T6: 平均值项:skeleton | U6: 平均值项:code | V6: 平均值项:parameter
A7: close | B7: gemini-2.5-flash | C7: 0.62 | D7: 0.3559 | E7: 0.3781 | F7: 0.3233 | G7: #DIV/0! | H7: 0.3592 | I7: 0.3947 | J7: 0.3086 | K7: #DIV/0! | L7: #DIV/0! | M7: 0.4426 | N7: 0.2981 | O7: #DIV/0! | P7: #DIV/0! | Q7: 0.433 | R7: 0.3657 | S7: #DIV/0! | T7: #DIV/0! | U7: 0.5723 | V7: 0.5056 | W7: 0.62 | X7: 0.35755 | Y7: 0.44414 | Z7: 0.36026
B8: gpt-3.5-turbo | C8: 0.4465 | D8: 0.1093 | E8: 0.1197 | F8: 0.4574 | G8: #DIV/0! | H8: 0.1335 | I8: 0.1312 | J8: 0.4741 | K8: #DIV/0! | L8: #DIV/0! | M8: 0.1184 | N8: 0.4312 | O8: #DIV/0! | P8: #DIV/0! | Q8: 0.1624 | R8: 0.4855 | S8: #DIV/0! | T8: #DIV/0! | U8: 0.4066 | V8: 0.4401 | W8: 0.4465 | X8: 0.1214 | Y8: 0.18766 | Z8: 0.45766
B9: gpt-5 | C9: 0.6351 | D9: 0.417 | E9: 0.4226 | F9: 0.367 | G9: #DIV/0! | H9: 0.4409 | I9: 0.4533 | J9: 0.5416 | K9: #DIV/0! | L9: #DIV/0! | M9: 0.434 | N9: 0.4239 | O9: #DIV/0! | P9: #DIV/0! | Q9: 0.4583 | R9: 0.4922 | S9: #DIV/0! | T9: #DIV/0! | U9: 0.5877 | V9: 0.6509 | W9: 0.6351 | X9: 0.42895 | Y9: 0.47118 | Z9: 0.49512
A10: open | B10: codellama-13b | S10: #DIV/0! | T10: #DIV/0! | U10: 0.0278 | V10: 0.0392 | W10: #DIV/0! | X10: #DIV/0! | Y10: 0.0278 | Z10: 0.0392
B11: codellama-34b | S11: #DIV/0! | T11: #DIV/0! | U11: 0.0259 | V11: 0 | W11: #DIV/0! | X11: #DIV/0! | Y11: 0.0259 | Z11: 0
B12: deepseek-coder-33b | S12: #DIV/0! | T12: #DIV/0! | U12: 0.271 | V12: 0.0436 | W12: #DIV/0! | X12: #DIV/0! | Y12: 0.271 | Z12: 0.0436
B13: deepseek-coder-6.7b | S13: #DIV/0! | T13: #DIV/0! | U13: 0.1381 | V13: 0.0039 | W13: #DIV/0! | X13: #DIV/0! | Y13: 0.1381 | Z13: 0.0039
B14: gemma3-12b | C14: 0.6186 | D14: 0.1858 | E14: 0.2086 | F14: 0.3262 | G14: #DIV/0! | H14: 0.1902 | I14: 0.1179 | J14: 0.1906 | K14: #DIV/0! | L14: #DIV/0! | M14: 0.1468 | N14: 0.1674 | O14: #DIV/0! | P14: #DIV/0! | Q14: 0.2087 | R14: 0.4221 | S14: #DIV/0! | T14: #DIV/0! | U14: 0.3606 | V14: 0.3393 | W14: 0.6186 | X14: 0.188 | Y14: 0.20852 | Z14: 0.28912
B15: gemma3-27b | C15: 0.5896 | D15: 0.1905 | E15: 0.145 | F15: 0.1488 | G15: #DIV/0! | H15: 0.1943 | I15: 0.1637 | J15: 0.2421 | K15: #DIV/0! | L15: #DIV/0! | M15: 0.316 | N15: 0.4257 | O15: #DIV/0! | P15: #DIV/0! | Q15: 0.3398 | R15: 0.4399 | S15: #DIV/0! | T15: #DIV/0! | U15: 0.4747 | V15: 0.4811 | W15: 0.5896 | X15: 0.1924 | Y15: 0.28784 | Z15: 0.34752
B16: gpt-oss-20b | C16: 0.5327 | D16: 0.1325 | E16: 0.2348 | F16: 0.2304 | G16: #DIV/0! | H16: 0.1267 | I16: 0.3067 | J16: 0.2937 | K16: #DIV/0! | L16: #DIV/0! | M16: 0.2538 | N16: 0.3055 | O16: #DIV/0! | P16: #DIV/0! | Q16: 0.3062 | R16: 0.3723 | S16: #DIV/0! | T16: #DIV/0! | U16: 0.4738 | V16: 0.3808 | W16: 0.5327 | X16: 0.1296 | Y16: 0.31506 | Z16: 0.31654
B17: llama3.1-8b | C17: 0.0665 | D17: 0.0365 | E17: 0.0523 | F17: 0.0483 | G17: #DIV/0! | H17: 0.0488 | I17: 0.0722 | J17: 0.0737 | K17: #DIV/0! | L17: #DIV/0! | M17: 0.0197 | N17: 0 | O17: #DIV/0! | P17: #DIV/0! | Q17: 0.0211 | R17: 0.0722 | S17: #DIV/0! | T17: #DIV/0! | U17: 0.0603 | V17: 0 | W17: 0.0665 | X17: 0.04265 | Y17: 0.04512 | Z17: 0.03884
B18: llama3.3-70b | C18: 0.4956 | D18: 0.1648 | E18: 0.2228 | F18: 0.3481 | G18: #DIV/0! | H18: 0.1752 | I18: 0.2767 | J18: 0.4205 | K18: #DIV/0! | L18: #DIV/0! | M18: 0.3432 | N18: 0.5099 | O18: #DIV/0! | P18: #DIV/0! | Q18: 0.2928 | R18: 0.4608 | S18: #DIV/0! | T18: #DIV/0! | U18: 0.3683 | V18: 0.401 | W18: 0.4956 | X18: 0.17 | Y18: 0.30076 | Z18: 0.42806
B19: phi4-14b | C19: 0.5782 | D19: 0 | E19: 0 | F19: 0 | G19: #DIV/0! | H19: 0.0291 | I19: 0.0281 | J19: 0.071 | K19: #DIV/0! | L19: #DIV/0! | M19: 0.3934 | N19: 0.4334 | O19: #DIV/0! | P19: #DIV/0! | Q19: 0.3619 | R19: 0.4564 | S19: #DIV/0! | T19: #DIV/0! | U19: 0.5108 | V19: 0.4693 | W19: 0.5782 | X19: 0.01455 | Y19: 0.25884 | Z19: 0.28602
B20: qwen2.5-coder-14b | S20: #DIV/0! | T20: #DIV/0! | U20: 0.021 | V20: 0.0376 | W20: #DIV/0! | X20: #DIV/0! | Y20: 0.021 | Z20: 0.0376
B21: qwen2.5-coder-32b | S21: #DIV/0! | T21: #DIV/0! | U21: 0.4206 | V21: 0.3059 | W21: #DIV/0! | X21: #DIV/0! | Y21: 0.4206 | Z21: 0.3059
B22: qwen3-14b | C22: 0.3866 | D22: 0.1039 | E22: 0.1789 | F22: 0.1654 | G22: #DIV/0! | H22: 0.1704 | I22: 0.201 | J22: 0.2819 | K22: #DIV/0! | L22: #DIV/0! | M22: 0.1971 | N22: 0.2602 | O22: #DIV/0! | P22: #DIV/0! | Q22: 0.2619 | R22: 0.3938 | S22: #DIV/0! | T22: #DIV/0! | U22: 0.4541 | V22: 0.3728 | W22: 0.3866 | X22: 0.13715 | Y22: 0.2586 | Z22: 0.29482
B23: qwen3-30b | C23: 0.3779 | D23: 0.1494 | E23: 0.1763 | F23: 0.1315 | G23: #DIV/0! | H23: 0.1652 | I23: 0.271 | J23: 0.186 | K23: #DIV/0! | L23: #DIV/0! | M23: 0.1971 | N23: 0.1653 | O23: #DIV/0! | P23: #DIV/0! | Q23: 0.1827 | R23: 0.1545 | S23: #DIV/0! | T23: #DIV/0! | U23: 0.5186 | V23: 0.265 | W23: 0.3779 | X23: 0.1573 | Y23: 0.26914 | Z23: 0.18046
A24: 总计 | C24: 0.48611818 | D24: 0.16778182 | E24: 0.19446364 | F24: 0.23149091 | G24: #DIV/0! | H24: 0.18486364 | I24: 0.21968182 | J24: 0.28034545 | K24: #DIV/0! | L24: #DIV/0! | M24: 0.26019091 | N24: 0.31096364 | O24: #DIV/0! | P24: #DIV/0! | Q24: 0.27534545 | R24: 0.37412727 | S24: #DIV/0! | T24: #DIV/0! | U24: 0.33483529 | V24: 0.27859412 | W24: 0.48611818 | X24: 0.17632273 | Y24: 0.26456885 | Z24: 0.29348033

Sheet Python
A1: date | B1: model | C1: mode | D1: timestamp | E1: level | F1: checklist | G1: skeleton | H1: code | I1: parameter | J1: source
A2: 20251024-1-python | B2: codellama-13b | C2: direct | D2: 20251027-124148 | E2: 3 | F2: None | G2: None | H2: 0.0278 | I2: 0.0392 | J2: open
A3: 20251024-1-python | B3: codellama-34b | C3: direct | D3: 20251027-120902 | E3: 3 | F3: None | G3: None | H3: 0.0259 | I3: 0 | J3: open
A4: 20251024-1-python | B4: deepseek-coder-33b | C4: direct | D4: 20251027-125123 | E4: 3 | F4: None | G4: None | H4: 0.271 | I4: 0.0436 | J4: open
A5: 20251024-1-python | B5: deepseek-coder-6.7b | C5: direct | D5: 20251027-131027 | E5: 3 | F5: None | G5: None | H5: 0.1381 | I5: 0.0039 | J5: open
A6: 20251024-1-python | B6: gemma3-12b | C6: cascade | D6: 20251024-131206 | E6: 1 | F6: 0.6186 | G6: 0.1858 | H6: 0.2086 | I6: 0.3262 | J6: open
A7: 20251024-1-python | B7: gemma3-12b | C7: cascade | D7: 20251024-152512 | E7: 2 | F7: None | G7: 0.1902 | H7: 0.1179 | I7: 0.1906 | J7: open
A8: 20251024-1-python | B8: gemma3-12b | C8: direct | D8: 20251025-035647 | E8: 1 | F8: None | G8: None | H8: 0.1468 | I8: 0.1674 | J8: open
A9: 20251024-1-python | B9: gemma3-12b | C9: direct | D9: 20251026-000440 | E9: 2 | F9: None | G9: None | H9: 0.2087 | I9: 0.4221 | J9: open
A10: 20251024-1-python | B10: gemma3-12b | C10: direct | D10: 20251026-124526 | E10: 3 | F10: None | G10: None | H10: 0.3606 | I10: 0.3393 | J10: open
A11: 20251024-1-python | B11: gemma3-27b | C11: cascade | D11: 20251024-164054 | E11: 1 | F11: 0.5896 | G11: 0.1905 | H11: 0.145 | I11: 0.1488 | J11: open
A12: 20251024-1-python | B12: gemma3-27b | C12: cascade | D12: 20251024-191431 | E12: 2 | F12: None | G12: 0.1943 | H12: 0.1637 | I12: 0.2421 | J12: open
A13: 20251024-1-python | B13: gemma3-27b | C13: direct | D13: 20251026-153202 | E13: 1 | F13: None | G13: None | H13: 0.316 | I13: 0.4257 | J13: open
A14: 20251024-1-python | B14: gemma3-27b | C14: direct | D14: 20251026-160357 | E14: 2 | F14: None | G14: None | H14: 0.3398 | I14: 0.4399 | J14: open
A15: 20251024-1-python | B15: gemma3-27b | C15: direct | D15: 20251026-163553 | E15: 3 | F15: None | G15: None | H15: 0.4747 | I15: 0.4811 | J15: open
A16: 20251024-1-python | B16: gpt-oss-20b | C16: cascade | D16: 20251027-144655 | E16: 1 | F16: 0.5327 | G16: 0.1325 | H16: 0.2348 | I16: 0.2304 | J16: open
A17: 20251024-1-python | B17: gpt-oss-20b | C17: cascade | D17: 20251027-231354 | E17: 2 | F17: None | G17: 0.1267 | H17: 0.3067 | I17: 0.2937 | J17: open
A18: 20251024-1-python | B18: gpt-oss-20b | C18: direct | D18: 20251028-103017 | E18: 1 | F18: None | G18: None | H18: 0.2538 | I18: 0.3055 | J18: open
A19: 20251024-1-python | B19: gpt-oss-20b | C19: direct | D19: 20251028-111620 | E19: 2 | F19: None | G19: None | H19: 0.3062 | I19: 0.3723 | J19: open
A20: 20251024-1-python | B20: gpt-oss-20b | C20: direct | D20: 20251028-115311 | E20: 3 | F20: None | G20: None | H20: 0.4738 | I20: 0.3808 | J20: open
A21: 20251024-1-python | B21: llama3.1-8b | C21: cascade | D21: 20251025-021937 | E21: 1 | F21: 0.0665 | G21: 0.0365 | H21: 0.0523 | I21: 0.0483 | J21: open
A22: 20251024-1-python | B22: llama3.1-8b | C22: cascade | D22: 20251025-023857 | E22: 2 | F22: None | G22: 0.0488 | H22: 0.0722 | I22: 0.0737 | J22: open
A23: 20251024-1-python | B23: llama3.1-8b | C23: direct | D23: 20251027-115021 | E23: 1 | F23: None | G23: None | H23: 0.0197 | I23: 0 | J23: open
A24: 20251024-1-python | B24: llama3.1-8b | C24: direct | D24: 20251027-115407 | E24: 2 | F24: None | G24: None | H24: 0.0211 | I24: 0.0722 | J24: open
A25: 20251024-1-python | B25: llama3.1-8b | C25: direct | D25: 20251027-115903 | E25: 3 | F25: None | G25: None | H25: 0.0603 | I25: 0 | J25: open
A26: 20251024-1-python | B26: llama3.3-70b | C26: cascade | D26: 20251024-221451 | E26: 1 | F26: 0.4956 | G26: 0.1648 | H26: 0.2228 | I26: 0.3481 | J26: open
A27: 20251024-1-python | B27: llama3.3-70b | C27: cascade | D27: 20251024-234322 | E27: 2 | F27: None | G27: 0.1752 | H27: 0.2767 | I27: 0.4205 | J27: open
A28: 20251024-1-python | B28: llama3.3-70b | C28: direct | D28: 20251026-185922 | E28: 1 | F28: None | G28: None | H28: 0.3432 | I28: 0.5099 | J28: open
A29: 20251024-1-python | B29: llama3.3-70b | C29: direct | D29: 20251026-201451 | E29: 2 | F29: None | G29: None | H29: 0.2928 | I29: 0.4608 | J29: open
A30: 20251024-1-python | B30: llama3.3-70b | C30: direct | D30: 20251027-023405 | E30: 3 | F30: None | G30: None | H30: 0.3683 | I30: 0.401 | J30: open
A31: 20251024-1-python | B31: phi4-14b | C31: cascade | D31: 20251024-203820 | E31: 1 | F31: 0.5782 | G31: 0 | H31: 0 | I31: 0 | J31: open
A32: 20251024-1-python | B32: phi4-14b | C32: cascade | D32: 20251024-205026 | E32: 2 | F32: None | G32: 0.0291 | H32: 0.0281 | I32: 0.071 | J32: open
A33: 20251024-1-python | B33: phi4-14b | C33: direct | D33: 20251026-171609 | E33: 1 | F33: None | G33: None | H33: 0.3934 | I33: 0.4334 | J33: open
A34: 20251024-1-python | B34: phi4-14b | C34: direct | D34: 20251026-173028 | E34: 2 | F34: None | G34: None | H34: 0.3619 | I34: 0.4564 | J34: open
A35: 20251024-1-python | B35: phi4-14b | C35: direct | D35: 20251026-174741 | E35: 3 | F35: None | G35: None | H35: 0.5108 | I35: 0.4693 | J35: open
A36: 20251024-1-python | B36: qwen2.5-coder-14b | C36: direct | D36: 20251026-184354 | E36: 3 | F36: None | G36: None | H36: 0.021 | I36: 0.0376 | J36: open
A37: 20251024-1-python | B37: qwen2.5-coder-32b | C37: direct | D37: 20251026-180746 | E37: 3 | F37: None | G37: None | H37: 0.4206 | I37: 0.3059 | J37: open
A38: 20251024-1-python | B38: qwen3-14b | C38: cascade | D38: 20251028-033643 | E38: 1 | F38: 0.3866 | G38: 0.1039 | H38: 0.1789 | I38: 0.1654 | J38: open
A39: 20251024-1-python | B39: qwen3-14b | C39: cascade | D39: 20251028-043312 | E39: 2 | F39: None | G39: 0.1704 | H39: 0.201 | I39: 0.2819 | J39: open
A40: 20251024-1-python | B40: qwen3-14b | C40: direct | D40: 20251028-151558 | E40: 1 | F40: None | G40: None | H40: 0.1971 | I40: 0.2602 | J40: open
...

Sheet Java Pivot
C3: mode | D3: level | E3: 值
C4: cascade | K4: direct | W4: 平均值项:checklist汇总 | X4: 平均值项:skeleton汇总 | Y4: 平均值项:code汇总 | Z4: 平均值项:parameter汇总
C5: 1 | G5: 2 | K5: 1 | O5: 2 | S5: 3
A6: source | B6: model | C6: 平均值项:checklist | D6: 平均值项:skeleton | E6: 平均值项:code | F6: 平均值项:parameter | G6: 平均值项:checklist | H6: 平均值项:skeleton | I6: 平均值项:code | J6: 平均值项:parameter | K6: 平均值项:checklist | L6: 平均值项:skeleton | M6: 平均值项:code | N6: 平均值项:parameter | O6: 平均值项:checklist | P6: 平均值项:skeleton | Q6: 平均值项:code | R6: 平均值项:parameter | S6: 平均值项:checklist | T6: 平均值项:skeleton | U6: 平均值项:code | V6: 平均值项:parameter
A7: close | B7: gemini-2.5-flash | C7: 0.5978 | D7: 0.2283 | E7: 0.2776 | F7: 0.4121 | G7: #DIV/0! | H7: 0.2378 | I7: 0.2732 | J7: 0.486 | K7: #DIV/0! | L7: #DIV/0! | M7: 0.3041 | N7: 0.4055 | O7: #DIV/0! | P7: #DIV/0! | Q7: 0.3306 | R7: 0.5204 | S7: #DIV/0! | T7: #DIV/0! | U7: 0.5596 | V7: 0.5319 | W7: 0.5978 | X7: 0.23305 | Y7: 0.34902 | Z7: 0.47118
B8: gpt-3.5-turbo | C8: 0.5027 | D8: 0.0915 | E8: 0.1507 | F8: 0.4872 | G8: #DIV/0! | H8: 0.1138 | I8: 0.1601 | J8: 0.44 | K8: #DIV/0! | L8: #DIV/0! | M8: 0.1641 | N8: 0.4951 | O8: #DIV/0! | P8: #DIV/0! | Q8: 0.2075 | R8: 0.489 | S8: #DIV/0! | T8: #DIV/0! | U8: 0.4298 | V8: 0.4228 | W8: 0.5027 | X8: 0.10265 | Y8: 0.22244 | Z8: 0.46682
B9: gpt-5 | C9: 0.6374 | D9: 0.3055 | E9: 0.3239 | F9: 0.5196 | G9: #DIV/0! | H9: 0.3101 | I9: 0.34 | J9: 0.5851 | K9: #DIV/0! | L9: #DIV/0! | M9: 0.2997 | N9: 0.4645 | O9: #DIV/0! | P9: #DIV/0! | Q9: 0.3434 | R9: 0.57 | S9: #DIV/0! | T9: #DIV/0! | U9: 0.6021 | V9: 0.5912 | W9: 0.6374 | X9: 0.3078 | Y9: 0.38182 | Z9: 0.54608
A10: open | B10: codellama-13b | S10: #DIV/0! | T10: #DIV/0! | U10: 0.1106 | V10: 0.1215 | W10: #DIV/0! | X10: #DIV/0! | Y10: 0.1106 | Z10: 0.1215
B11: codellama-34b | S11: #DIV/0! | T11: #DIV/0! | U11: 0.0632 | V11: 0.0249 | W11: #DIV/0! | X11: #DIV/0! | Y11: 0.0632 | Z11: 0.0249
B12: deepseek-coder-33b | S12: #DIV/0! | T12: #DIV/0! | U12: 0.2233 | V12: 0.0867 | W12: #DIV/0! | X12: #DIV/0! | Y12: 0.2233 | Z12: 0.0867
B13: deepseek-coder-6.7b | S13: #DIV/0! | T13: #DIV/0! | U13: 0.2515 | V13: 0.0109 | W13: #DIV/0! | X13: #DIV/0! | Y13: 0.2515 | Z13: 0.0109
B14: gemma3-12b | C14: 0.621 | D14: 0.1658 | E14: 0.193 | F14: 0.4516 | G14: #DIV/0! | H14: 0.1708 | I14: 0.1778 | J14: 0.3064 | K14: #DIV/0! | L14: #DIV/0! | M14: 0.1562 | N14: 0.3333 | O14: #DIV/0! | P14: #DIV/0! | Q14: 0.2328 | R14: 0.5405 | S14: #DIV/0! | T14: #DIV/0! | U14: 0.3641 | V14: 0.3177 | W14: 0.621 | X14: 0.1683 | Y14: 0.22478 | Z14: 0.3899
B15: gemma3-27b | C15: 0.6525 | D15: 0.2263 | E15: 0.2611 | F15: 0.4598 | G15: #DIV/0! | H15: 0.2199 | I15: 0.2174 | J15: 0.3895 | K15: #DIV/0! | L15: #DIV/0! | M15: 0.2097 | N15: 0.5066 | O15: #DIV/0! | P15: #DIV/0! | Q15: 0.2084 | R15: 0.3452 | S15: #DIV/0! | T15: #DIV/0! | U15: 0.517 | V15: 0.4072 | W15: 0.6525 | X15: 0.2231 | Y15: 0.28272 | Z15: 0.42166
B16: gpt-oss-20b | C16: 0.6496 | D16: 0.177 | E16: 0.2385 | F16: 0.3284 | G16: #DIV/0! | H16: 0.1109 | I16: 0.2839 | J16: 0.4611 | K16: #DIV/0! | L16: #DIV/0! | M16: 0.2259 | N16: 0.2181 | O16: #DIV/0! | P16: #DIV/0! | Q16: 0.3178 | R16: 0.3635 | S16: #DIV/0! | T16: #DIV/0! | U16: 0.4085 | V16: 0.2301 | W16: 0.6496 | X16: 0.14395 | Y16: 0.29492 | Z16: 0.32024
B17: llama3.1-8b | C17: 0.0413 | D17: 0.0803 | E17: 0.0586 | F17: 0 | G17: #DIV/0! | H17: 0.0767 | I17: 0.0342 | J17: 0 | K17: #DIV/0! | L17: #DIV/0! | M17: 0.0809 | N17: 0.0942 | O17: #DIV/0! | P17: #DIV/0! | Q17: 0.0343 | R17: 0 | S17: #DIV/0! | T17: #DIV/0! | U17: 0.0777 | V17: 0 | W17: 0.0413 | X17: 0.0785 | Y17: 0.05714 | Z17: 0.01884
B18: llama3.3-70b | C18: 0.4919 | D18: 0.2142 | E18: 0.0391 | F18: 0.066 | G18: #DIV/0! | H18: 0.1789 | I18: 0.0713 | J18: 0.2202 | K18: #DIV/0! | L18: #DIV/0! | M18: 0.0082 | N18: 0.0171 | O18: #DIV/0! | P18: #DIV/0! | Q18: 0.0607 | R18: 0.1592 | S18: #DIV/0! | T18: #DIV/0! | U18: 0.4753 | V18: 0.4392 | W18: 0.4919 | X18: 0.19655 | Y18: 0.13092 | Z18: 0.18034
B19: phi4-14b | C19: 0.5781 | D19: 0.0804 | E19: 0.151 | F19: 0.2605 | G19: #DIV/0! | H19: 0.0893 | I19: 0.1794 | J19: 0.2805 | K19: #DIV/0! | L19: #DIV/0! | M19: 0.1941 | N19: 0.4251 | O19: #DIV/0! | P19: #DIV/0! | Q19: 0.2485 | R19: 0.4303 | S19: #DIV/0! | T19: #DIV/0! | U19: 0.5527 | V19: 0.3858 | W19: 0.5781 | X19: 0.08485 | Y19: 0.26514 | Z19: 0.35644
B20: qwen2.5-coder-14b | S20: #DIV/0! | T20: #DIV/0! | U20: 0.3567 | V20: 0.3324 | W20: #DIV/0! | X20: #DIV/0! | Y20: 0.3567 | Z20: 0.3324
B21: qwen2.5-coder-32b | S21: #DIV/0! | T21: #DIV/0! | U21: 0.4376 | V21: 0.3844 | W21: #DIV/0! | X21: #DIV/0! | Y21: 0.4376 | Z21: 0.3844
B22: qwen3-14b | C22: 0.5993 | D22: 0.0542 | E22: 0.192 | F22: 0.2517 | G22: #DIV/0! | H22: 0.0625 | I22: 0.2112 | J22: 0.3241 | K22: #DIV/0! | L22: #DIV/0! | M22: 0.2186 | N22: 0.3572 | O22: #DIV/0! | P22: #DIV/0! | Q22: 0.2119 | R22: 0.173 | S22: #DIV/0! | T22: #DIV/0! | U22: 0.2843 | V22: 0.2243 | W22: 0.5993 | X22: 0.05835 | Y22: 0.2236 | Z22: 0.26606
B23: qwen3-30b | C23: 0.3824 | D23: 0.0682 | E23: 0.189 | F23: 0.389 | G23: #DIV/0! | H23: 0.0536 | I23: 0.186 | J23: 0.2901 | K23: #DIV/0! | L23: #DIV/0! | M23: 0.1453 | N23: 0.2922 | O23: #DIV/0! | P23: #DIV/0! | Q23: 0.0623 | R23: 0.1372 | S23: #DIV/0! | T23: #DIV/0! | U23: 0.4322 | V23: 0.2292 | W23: 0.3824 | X23: 0.0609 | Y23: 0.20296 | Z23: 0.26754
A24: 总计 | C24: 0.52309091 | D24: 0.15379091 | E24: 0.18859091 | F24: 0.32962727 | G24: #DIV/0! | H24: 0.14766364 | I24: 0.19404545 | J24: 0.34390909 | K24: #DIV/0! | L24: #DIV/0! | M24: 0.18243636 | N24: 0.32808182 | O24: #DIV/0! | P24: #DIV/0! | Q24: 0.20529091 | R24: 0.33893636 | S24: #DIV/0! | T24: #DIV/0! | U24: 0.36154118 | V24: 0.27883529 | W24: 0.52309091 | X24: 0.15072727 | Y24: 0.23967541 | Z24: 0.31944754

Sheet Java
A1: date | B1: model | C1: mode | D1: timestamp | E1: level | F1: checklist | G1: skeleton | H1: code | I1: parameter | J1: source
A2: 20251028-1-jsdirect3 | B2: codellama-13b | C2: direct | D2: 20251029-033943 | E2: 3 | F2: None | G2: None | H2: 0.1106 | I2: 0.1215 | J2: open
A3: 20251028-1-jsdirect3 | B3: codellama-34b | C3: direct | D3: 20251029-003016 | E3: 3 | F3: None | G3: None | H3: 0.0632 | I3: 0.0249 | J3: open
A4: 20251028-1-jsdirect3 | B4: deepseek-coder-33b | C4: direct | D4: 20251029-034434 | E4: 3 | F4: None | G4: None | H4: 0.2233 | I4: 0.0867 | J4: open
A5: 20251028-1-jsdirect3 | B5: deepseek-coder-6.7b | C5: direct | D5: 20251029-035859 | E5: 3 | F5: None | G5: None | H5: 0.2515 | I5: 0.0109 | J5: open
A6: 20251029-1-java-opensources | B6: gemma3-12b | C6: cascade | D6: 20251029-141855 | E6: 1 | F6: 0.621 | G6: 0.1658 | H6: 0.193 | I6: 0.4516 | J6: open
A7: 20251029-1-java-opensources | B7: gemma3-12b | C7: cascade | D7: 20251029-172111 | E7: 2 | F7: None | G7: 0.1708 | H7: 0.1778 | I7: 0.3064 | J7: open
A8: 20251029-1-java-opensources | B8: gemma3-12b | C8: direct | D8: 20251029-222906 | E8: 1 | F8: None | G8: None | H8: 0.1562 | I8: 0.3333 | J8: open
A9: 20251029-1-java-opensources | B9: gemma3-12b | C9: direct | D9: 20251030-034426 | E9: 2 | F9: None | G9: None | H9: 0.2328 | I9: 0.5405 | J9: open
A10: 20251028-1-jsdirect3 | B10: gemma3-12b | C10: direct | D10: 20251028-202130 | E10: 3 | F10: None | G10: None | H10: 0.3641 | I10: 0.3177 | J10: open
A11: 20251029-1-java-opensources | B11: gemma3-27b | C11: cascade | D11: 20251029-175440 | E11: 1 | F11: 0.6525 | G11: 0.2263 | H11: 0.2611 | I11: 0.4598 | J11: open
A12: 20251029-1-java-opensources | B12: gemma3-27b | C12: cascade | D12: 20251029-194639 | E12: 2 | F12: None | G12: 0.2199 | H12: 0.2174 | I12: 0.3895 | J12: open
A13: 20251029-1-java-opensources | B13: gemma3-27b | C13: direct | D13: 20251030-043918 | E13: 1 | F13: None | G13: None | H13: 0.2097 | I13: 0.5066 | J13: open
A14: 20251029-1-java-opensources | B14: gemma3-27b | C14: direct | D14: 20251030-071615 | E14: 2 | F14: None | G14: None | H14: 0.2084 | I14: 0.3452 | J14: open
A15: 20251028-1-jsdirect3 | B15: gemma3-27b | C15: direct | D15: 20251028-204251 | E15: 3 | F15: None | G15: None | H15: 0.517 | I15: 0.4072 | J15: open
A16: 20251029-1-java-opensources | B16: gpt-oss-20b | C16: cascade | D16: 20251029-125403 | E16: 1 | F16: 0.6496 | G16: 0.177 | H16: 0.2385 | I16: 0.3284 | J16: open
A17: 20251029-1-java-opensources | B17: gpt-oss-20b | C17: cascade | D17: 20251029-132951 | E17: 2 | F17: None | G17: 0.1109 | H17: 0.2839 | I17: 0.4611 | J17: open
A18: 20251029-1-java-opensources | B18: gpt-oss-20b | C18: direct | D18: 20251029-204820 | E18: 1 | F18: None | G18: None | H18: 0.2259 | I18: 0.2181 | J18: open
A19: 20251029-1-java-opensources | B19: gpt-oss-20b | C19: direct | D19: 20251029-211634 | E19: 2 | F19: None | G19: None | H19: 0.3178 | I19: 0.3635 | J19: open
A20: 20251028-1-jsdirect3 | B20: gpt-oss-20b | C20: direct | D20: 20251028-201946 | E20: 3 | F20: None | G20: None | H20: 0.4085 | I20: 0.2301 | J20: open
A21: 20251029-1-java-opensources | B21: llama3.1-8b | C21: cascade | D21: 20251029-184641 | E21: 1 | F21: 0.0413 | G21: 0.0803 | H21: 0.0586 | I21: 0 | J21: open
A22: 20251029-1-java-opensources | B22: llama3.1-8b | C22: cascade | D22: 20251029-191234 | E22: 2 | F22: None | G22: 0.0767 | H22: 0.0342 | I22: 0 | J22: open
A23: 20251029-1-java-opensources | B23: llama3.1-8b | C23: direct | D23: 20251030-104414 | E23: 1 | F23: None | G23: None | H23: 0.0809 | I23: 0.0942 | J23: open
A24: 20251029-1-java-opensources | B24: llama3.1-8b | C24: direct | D24: 20251030-105514 | E24: 2 | F24: None | G24: None | H24: 0.0343 | I24: 0 | J24: open
A25: 20251028-1-jsdirect3 | B25: llama3.1-8b | C25: direct | D25: 20251029-001818 | E25: 3 | F25: None | G25: None | H25: 0.0777 | I25: 0 | J25: open
A26: 20251029-1-java-opensources | B26: llama3.3-70b | C26: cascade | D26: 20251029-154027 | E26: 1 | F26: 0.4919 | G26: 0.2142 | H26: 0.0391 | I26: 0.066 | J26: open
A27: 20251029-1-java-opensources | B27: llama3.3-70b | C27: cascade | D27: 20251029-171738 | E27: 2 | F27: None | G27: 0.1789 | H27: 0.0713 | I27: 0.2202 | J27: open
A28: 20251029-1-java-opensources | B28: llama3.3-70b | C28: direct | D28: 20251029-234940 | E28: 1 | F28: None | G28: None | H28: 0.0082 | I28: 0.0171 | J28: open
A29: 20251029-1-java-opensources | B29: llama3.3-70b | C29: direct | D29: 20251030-051120 | E29: 2 | F29: None | G29: None | H29: 0.0607 | I29: 0.1592 | J29: open
A30: 20251028-1-jsdirect3 | B30: llama3.3-70b | C30: direct | D30: 20251028-230205 | E30: 3 | F30: None | G30: None | H30: 0.4753 | I30: 0.4392 | J30: open
A31: 20251029-1-java-opensources | B31: phi4-14b | C31: cascade | D31: 20251029-192418 | E31: 1 | F31: 0.5781 | G31: 0.0804 | H31: 0.151 | I31: 0.2605 | J31: open
A32: 20251029-1-java-opensources | B32: phi4-14b | C32: cascade | D32: 20251029-195320 | E32: 2 | F32: None | G32: 0.0893 | H32: 0.1794 | I32: 0.2805 | J32: open
A33: 20251029-1-java-opensources | B33: phi4-14b | C33: direct | D33: 20251030-111338 | E33: 1 | F33: None | G33: None | H33: 0.1941 | I33: 0.4251 | J33: open
A34: 20251029-1-java-opensources | B34: phi4-14b | C34: direct | D34: 20251030-113309 | E34: 2 | F34: None | G34: None | H34: 0.2485 | I34: 0.4303 | J34: open
A35: 20251028-1-jsdirect3 | B35: phi4-14b | C35: direct | D35: 20251028-212851 | E35: 3 | F35: None | G35: None | H35: 0.5527 | I35: 0.3858 | J35: open
A36: 20251028-1-jsdirect3 | B36: qwen2.5-coder-14b | C36: direct | D36: 20251028-224242 | E36: 3 | F36: None | G36: None | H36: 0.3567 | I36: 0.3324 | J36: open
A37: 20251028-1-jsdirect3 | B37: qwen2.5-coder-32b | C37: direct | D37: 20251028-215453 | E37: 3 | F37: None | G37: None | H37: 0.4376 | I37: 0.3844 | J37: open
A38: 20251029-1-java-opensources | B38: qwen3-14b | C38: cascade | D38: 20251029-125440 | E38: 1 | F38: 0.5993 | G38: 0.0542 | H38: 0.192 | I38: 0.2517 | J38: open
A39: 20251029-1-java-opensources | B39: qwen3-14b | C39: cascade | D39: 20251029-132743 | E39: 2 | F39: None | G39: 0.0625 | H39: 0.2112 | I39: 0.3241 | J39: open
A40: 20251029-1-java-opensources | B40: qwen3-14b | C40: direct | D40: 20251029-201841 | E40: 1 | F40: None | G40: None | H40: 0.2186 | I40: 0.3572 | J40: open
...

Sheet JavaScript Pivot
C3: mode | D3: level | E3: 值
C4: cascade | K4: direct | W4: 平均值项:checklist汇总 | X4: 平均值项:skeleton汇总 | Y4: 平均值项:code汇总 | Z4: 平均值项:parameter汇总
C5: 1 | G5: 2 | K5: 1 | O5: 2 | S5: 3
A6: source | B6: model | C6: 平均值项:checklist | D6: 平均值项:skeleton | E6: 平均值项:code | F6: 平均值项:parameter | G6: 平均值项:checklist | H6: 平均值项:skeleton | I6: 平均值项:code | J6: 平均值项:parameter | K6: 平均值项:checklist | L6: 平均值项:skeleton | M6: 平均值项:code | N6: 平均值项:parameter | O6: 平均值项:checklist | P6: 平均值项:skeleton | Q6: 平均值项:code | R6: 平均值项:parameter | S6: 平均值项:checklist | T6: 平均值项:skeleton | U6: 平均值项:code | V6: 平均值项:parameter
A7: close | B7: gemini-2.5-flash | C7: 0.6047 | D7: 0.2272 | E7: 0.2559 | F7: 0.3298 | G7: #DIV/0! | H7: 0.3454 | I7: 0.2788 | J7: 0.4143 | K7: #DIV/0! | L7: #DIV/0! | M7: 0.2205 | N7: 0.283 | O7: #DIV/0! | P7: #DIV/0! | Q7: 0.3344 | R7: 0.3897 | S7: #DIV/0! | T7: #DIV/0! | U7: 0.5448 | V7: 0.5706 | W7: 0.6047 | X7: 0.2863 | Y7: 0.32688 | Z7: 0.39748
B8: gpt-3.5-turbo | C8: 0.484 | D8: 0.1041 | E8: 0.1305 | F8: 0.5032 | G8: #DIV/0! | H8: 0.1073 | I8: 0.129 | J8: 0.5188 | K8: #DIV/0! | L8: #DIV/0! | M8: 0.1363 | N8: 0.4717 | O8: #DIV/0! | P8: #DIV/0! | Q8: 0.2181 | R8: 0.485 | S8: #DIV/0! | T8: #DIV/0! | U8: 0.4534 | V8: 0.4707 | W8: 0.484 | X8: 0.1057 | Y8: 0.21346 | Z8: 0.48988
B9: gpt-5 | C9: 0.6463 | D9: 0.3106 | E9: 0.3151 | F9: 0.4579 | G9: #DIV/0! | H9: 0.3154 | I9: 0.3341 | J9: 0.5817 | K9: #DIV/0! | L9: #DIV/0! | M9: 0.2624 | N9: 0.4306 | O9: #DIV/0! | P9: #DIV/0! | Q9: 0.3498 | R9: 0.5412 | S9: #DIV/0! | T9: #DIV/0! | U9: 0.5577 | V9: 0.5875 | W9: 0.6463 | X9: 0.313 | Y9: 0.36382 | Z9: 0.51978
A10: open | B10: codellama-13b | S10: #DIV/0! | T10: #DIV/0! | U10: 0.1106 | V10: 0.1215 | W10: #DIV/0! | X10: #DIV/0! | Y10: 0.1106 | Z10: 0.1215
B11: codellama-34b | S11: #DIV/0! | T11: #DIV/0! | U11: 0.0632 | V11: 0.0249 | W11: #DIV/0! | X11: #DIV/0! | Y11: 0.0632 | Z11: 0.0249
B12: deepseek-coder-33b | S12: #DIV/0! | T12: #DIV/0! | U12: 0.2233 | V12: 0.0867 | W12: #DIV/0! | X12: #DIV/0! | Y12: 0.2233 | Z12: 0.0867
B13: deepseek-coder-6.7b | S13: #DIV/0! | T13: #DIV/0! | U13: 0.2515 | V13: 0.0109 | W13: #DIV/0! | X13: #DIV/0! | Y13: 0.2515 | Z13: 0.0109
B14: gemma3-12b | C14: 0.6215 | D14: 0.2014 | E14: 0.1973 | F14: 0.4754 | G14: #DIV/0! | H14: 0.2263 | I14: 0.1854 | J14: 0.3836 | K14: #DIV/0! | L14: #DIV/0! | M14: 0.1678 | N14: 0.3811 | O14: #DIV/0! | P14: #DIV/0! | Q14: 0.0975 | R14: 0.1938 | S14: #DIV/0! | T14: #DIV/0! | U14: 0.3641 | V14: 0.3177 | W14: 0.6215 | X14: 0.21385 | Y14: 0.20242 | Z14: 0.35032
B15: gemma3-27b | C15: 0.6525 | D15: 0.2029 | E15: 0.2352 | F15: 0.5498 | G15: #DIV/0! | H15: 0.2173 | I15: 0.2442 | J15: 0.5049 | K15: #DIV/0! | L15: #DIV/0! | M15: 0.2228 | N15: 0.5042 | O15: #DIV/0! | P15: #DIV/0! | Q15: 0.2499 | R15: 0.4669 | S15: #DIV/0! | T15: #DIV/0! | U15: 0.517 | V15: 0.4072 | W15: 0.6525 | X15: 0.2101 | Y15: 0.29382 | Z15: 0.4866
B16: gpt-oss-20b | C16: 0.5731 | D16: 0.157 | E16: 0.2252 | F16: 0.4947 | G16: #DIV/0! | H16: 0.1992 | I16: 0.1871 | J16: 0.2636 | K16: #DIV/0! | L16: #DIV/0! | M16: 0.1749 | N16: 0.2462 | O16: #DIV/0! | P16: #DIV/0! | Q16: 0.2697 | R16: 0.3058 | S16: #DIV/0! | T16: #DIV/0! | U16: 0.4085 | V16: 0.2301 | W16: 0.5731 | X16: 0.1781 | Y16: 0.25308 | Z16: 0.30808
B17: llama3.1-8b | C17: 0.0413 | D17: 0.0404 | E17: 0.0929 | F17: 0 | G17: #DIV/0! | H17: 0.0346 | I17: 0.0953 | J17: 0.038 | K17: #DIV/0! | L17: #DIV/0! | M17: 0.0479 | N17: 0 | O17: #DIV/0! | P17: #DIV/0! | Q17: 0.1617 | R17: 0.0111 | S17: #DIV/0! | T17: #DIV/0! | U17: 0.0777 | V17: 0 | W17: 0.0413 | X17: 0.0375 | Y17: 0.0951 | Z17: 0.00982
B18: llama3.3-70b | C18: 0.4919 | D18: 0.1837 | E18: 0.2525 | F18: 0.4825 | G18: #DIV/0! | H18: 0.2101 | I18: 0.2787 | J18: 0.467 | K18: #DIV/0! | L18: #DIV/0! | M18: 0.2054 | N18: 0.3593 | O18: #DIV/0! | P18: #DIV/0! | Q18: 0.2497 | R18: 0.4965 | S18: #DIV/0! | T18: #DIV/0! | U18: 0.4753 | V18: 0.4392 | W18: 0.4919 | X18: 0.1969 | Y18: 0.29232 | Z18: 0.4489
