Workbook

Sheet Formatted
A2: Model | B2: Level 1 Cascade | C2: Level 1 E2E | D2: Level 2 Cascade | E2: Level 2 E2E | F2: Level 3 | G2: Avg.
A3: Close-source LLMs
A4: Gemini 2.5-flash | B4: =Calculation!B26 -> 0.072769953 | C4: =Calculation!C26 -> 0.16666667 | D4: =Calculation!D26 -> 0.13615023 | E4: =Calculation!E26 -> 0.14788732 | F4: =Calculation!F26 -> 0.25117371 | G4: =Calculation!G26 -> 0.15492958 | K4: Gemini-2.5-flash | L4: =Calculation!L27 -> 0.077464789 | M4: =Calculation!M27 -> 0.063380282 | N4: =Calculation!N27 -> 0.077464789 | O4: =Calculation!O27 -> 0.1971831 | P4: =Calculation!P27 -> 0.1584507 | Q4: =Calculation!Q27 -> 0.1443662 | R4: =Calculation!R27 -> 0.11971831
A5: GPT-3.5-turbo | B5: =Calculation!B27 -> 0.024647887 | C5: =Calculation!C27 -> 0.023474178 | D5: =Calculation!D27 -> 0.024647887 | E5: =Calculation!E27 -> 0.024647887 | F5: =Calculation!F27 -> 0.038732394 | G5: =Calculation!G27 -> 0.027230047 | K5: GPT-3.5-turbo | L5: =Calculation!L28 -> 0.024647887 | M5: =Calculation!M28 -> 0.024647887 | N5: =Calculation!N28 -> 0.024647887 | O5: =Calculation!O28 -> 0.024647887 | P5: =Calculation!P28 -> 0.024647887 | Q5: =Calculation!Q28 -> 0.021126761 | R5: =Calculation!R28 -> 0.024061033
A6: GPT-5 | B6: =Calculation!B28 -> 0.12558685 | C6: =Calculation!C28 -> 0.23122066 | D6: =Calculation!D28 -> 0.34624413 | E6: =Calculation!E28 -> 0.33215962 | F6: =Calculation!F28 -> 0.44600939 | G6: =Calculation!G28 -> 0.29624413 | K6: GPT-5 | L6: =Calculation!L29 -> 0.16197183 | M6: =Calculation!M29 -> 0.052816901 | N6: =Calculation!N29 -> 0.16197183 | O6: =Calculation!O29 -> 0.27112676 | P6: =Calculation!P29 -> 0.18309859 | Q6: =Calculation!Q29 -> 0.23943662 | R6: =Calculation!R29 -> 0.17840376
A7: Open-source LLMs
A8: Gemma-3-12B | B8: =Calculation!B34 -> 0.029342723 | C8: =Calculation!C34 -> 0.030516432 | D8: =Calculation!D34 -> 0.0058685447 | E8: =Calculation!E34 -> 0.016431925 | F8: =Calculation!F34 -> 0.071596244 | G8: =Calculation!G34 -> 0.030751174 | K8: =Calculation!K30 -> Gemma-3-12B | L8: =Calculation!L30 -> 0.031690141 | M8: =Calculation!M30 -> 0.021126761 | N8: =Calculation!N30 -> 0.035211268 | O8: =Calculation!O30 -> 0.01056338 | P8: =Calculation!P30 -> 0.021126761 | Q8: =Calculation!Q30 -> 0.059859155 | R8: =Calculation!R30 -> 0.029929578
A9: Gemma-3-27B | B9: =Calculation!B35 -> 0.037558685 | C9: =Calculation!C35 -> 0.030516432 | D9: =Calculation!D35 -> 0.026995305 | E9: =Calculation!E35 -> 0.031690141 | F9: =Calculation!F35 -> 0.1056338 | G9: =Calculation!G35 -> 0.046478873 | K9: =Calculation!K31 -> Gemma-3-27B | L9: =Calculation!L31 -> 0.014084507 | M9: =Calculation!M31 -> 0.028169014 | N9: =Calculation!N31 -> 0.070422535 | O9: =Calculation!O31 -> 0.024647887 | P9: =Calculation!P31 -> 0.017605634 | Q9: =Calculation!Q31 -> 0.049295775 | R9: =Calculation!R31 -> 0.034037559
A10: GPT-oss-20B | B10: =Calculation!B36 -> 0.048122066 | C10: =Calculation!C36 -> 0.075117371 | D10: =Calculation!D36 -> 0.056338028 | E10: =Calculation!E36 -> 0.062206573 | F10: =Calculation!F36 -> 0.10446009 | G10: =Calculation!G36 -> 0.069248826 | K10: =Calculation!K32 -> GPT-oss-20B | L10: =Calculation!L32 -> 0.056338028 | M10: =Calculation!M32 -> 0.031690141 | N10: =Calculation!N32 -> 0.056338028 | O10: =Calculation!O32 -> 0.052816901 | P10: =Calculation!P32 -> 0.063380282 | Q10: =Calculation!Q32 -> 0.10915493 | R10: =Calculation!R32 -> 0.061619718
A11: Llama3.1-8B | B11: =Calculation!B37 -> 0.0082159626 | C11: =Calculation!C37 -> 0.002347418 | D11: =Calculation!D37 -> 0.011737089 | E11: =Calculation!E37 -> 0.0070422536 | F11: =Calculation!F37 -> 0.0035211269 | G11: =Calculation!G37 -> 0.0065727701 | K11: =Calculation!K33 -> Llama3.1-8B | L11: =Calculation!L33 -> 0.014084507 | M11: =Calculation!M33 -> 0.007042254 | N11: =Calculation!N33 -> 0.0035211268 | O11: =Calculation!O33 -> 0 | P11: =Calculation!P33 -> 0.007042254 | Q11: =Calculation!Q33 -> 0 | R11: =Calculation!R33 -> 0.0052816903
A12: Llama3.3-70B | B12: =Calculation!B38 -> 0.046948357 | C12: =Calculation!C38 -> 0.078638498 | D12: =Calculation!D38 -> 0.045774648 | E12: =Calculation!E38 -> 0.078638498 | F12: =Calculation!F38 -> 0.080985916 | G12: =Calculation!G38 -> 0.066197183 | K12: =Calculation!K34 -> Llama3.3-70B | L12: =Calculation!L34 -> 0.024647887 | M12: =Calculation!M34 -> 0.003521127 | N12: =Calculation!N34 -> 0.11267606 | O12: =Calculation!O34 -> 0.10211268 | P12: =Calculation!P34 -> 0 | Q12: =Calculation!Q34 -> 0.13380282 | R12: =Calculation!R34 -> 0.062793427
A13: Phi4-14B | B13: =Calculation!B39 -> 0.02112676 | C13: =Calculation!C39 -> 0.0657277 | D13: =Calculation!D39 -> 0.030516432 | E13: =Calculation!E39 -> 0.062206573 | F13: =Calculation!F39 -> 0.089201878 | G13: =Calculation!G39 -> 0.053755868 | K13: =Calculation!K35 -> Phi4-14B | L13: =Calculation!L35 -> 0 | M13: =Calculation!M35 -> 0.01056338 | N13: =Calculation!N35 -> 0.052816901 | O13: =Calculation!O35 -> 0.049295775 | P13: =Calculation!P35 -> 0.049295775 | Q13: =Calculation!Q35 -> 0.098591549 | R13: =Calculation!R35 -> 0.04342723
A14: Qwen3-14B | B14: =Calculation!B42 -> 0.022300469 | C14: =Calculation!C42 -> 0.028169014 | D14: =Calculation!D42 -> 0.018779343 | E14: =Calculation!E42 -> 0.016431925 | F14: =Calculation!F42 -> 0.030516432 | G14: =Calculation!G42 -> 0.023239437 | K14: =Calculation!K36 -> Qwen3-14B | L14: =Calculation!L36 -> 0 | M14: =Calculation!M36 -> 0.014084507 | N14: =Calculation!N36 -> 0.052816901 | O14: =Calculation!O36 -> 0.021126761 | P14: =Calculation!P36 -> 0.031690141 | Q14: =Calculation!Q36 -> 0.031690141 | R14: =Calculation!R36 -> 0.025234742
A15: Qwen3-30B | B15: =Calculation!B43 -> 0.046948357 | C15: =Calculation!C43 -> 0.039906103 | D15: =Calculation!D43 -> 0.070422535 | E15: =Calculation!E43 -> 0.042253521 | F15: =Calculation!F43 -> 0.092723005 | G15: =Calculation!G43 -> 0.058450704 | K15: =Calculation!K37 -> Qwen3-30B | L15: =Calculation!L37 -> 0.045774648 | M15: =Calculation!M37 -> 0.045774648 | N15: =Calculation!N37 -> 0.049295775 | O15: =Calculation!O37 -> 0.038732394 | P15: =Calculation!P37 -> 0.052816901 | Q15: =Calculation!Q37 -> 0.028169014 | R15: =Calculation!R37 -> 0.04342723
A16: Code generation LLMs | K16: =Calculation!K38 -> All Avg. | L16: =Calculation!L38 -> 0.040973111 | M16: =Calculation!M38 -> 0.027528809 | N16: =Calculation!N38 -> 0.063380282 | O16: =Calculation!O38 -> 0.072023047 | P16: =Calculation!P38 -> 0.055377721 | Q16: =Calculation!Q38 -> 0.083226633 | R16: =Calculation!R38 -> 0.057084934
A17: CodeLlama-13B | B17: - | C17: - | D17: - | E17: - | F17: =Calculation!F29 -> 0.0070422537 | G17: -
A18: CodeLlama-34B | B18: - | C18: - | D18: - | E18: - | F18: =Calculation!F30 -> 0 | G18: -
A19: CodeLlama-70B | B19: - | C19: - | D19: - | E19: - | F19: =Calculation!F31 -> 0 | G19: -
A20: DeepSeek-Coder-33B | B20: - | C20: - | D20: - | E20: - | F20: =Calculation!F32 -> 0.025821596 | G20: -
A21: DeepSeek-Coder-6.7B | B21: - | C21: - | D21: - | E21: - | F21: =Calculation!F33 -> 0.0093896714 | G21: -
A22: Qwen2.5-Coder-14B | B22: - | C22: - | D22: - | E22: - | F22: =Calculation!F40 -> 0.030516432 | G22: -
A23: Qwen2.5-Coder-32B | B23: - | C23: - | D23: - | E23: - | F23: =Calculation!F41 -> 0.075117371 | G23: -
A24: Avg. | B24: =Calculation!B44 -> 0.043960734 | C24: =Calculation!C44 -> 0.070209134 | D24: =Calculation!D44 -> 0.070315834 | E24: =Calculation!E44 -> 0.074690568 | F24: =Calculation!F44 -> 0.08124674 | G24: =Calculation!G44 -> 0.047926448

Sheet Calculation
A1: Python | B1: 1 | C1: 1 | D1: 2 | E1: 2 | F1: 3 | H1: Java | I1: 1 | J1: 1 | K1: 2 | L1: 2 | M1: 3 | O1: JavaScript | P1: 1 | Q1: 1 | R1: 2 | S1: 2 | T1: 3
A2: model | B2: cascade | C2: direct | D2: cascade | E2: direct | F2: direct | H2: model | I2: cascade | J2: direct | K2: cascade | L2: direct | M2: direct | O2: ='JavaScript Pivot'!B5 -> model | P2: ='JavaScript Pivot'!C5 -> cascade | Q2: ='JavaScript Pivot'!D5 -> direct | R2: ='JavaScript Pivot'!E5 -> cascade | S2: ='JavaScript Pivot'!F5 -> direct | T2: ='JavaScript Pivot'!G5 -> direct
A3: ='Python Pivot'!B6 -> gemini-2.5-flash | B3: ='Python Pivot'!C6 -> 0.077464789 | C3: ='Python Pivot'!D6 -> 0.1971831 | D3: ='Python Pivot'!E6 -> 0.12676056 | E3: ='Python Pivot'!F6 -> 0.19014085 | F3: ='Python Pivot'!G6 -> 0.18309859 | H3: ='Java Pivot'!B6 -> gemini-2.5-flash | I3: ='Java Pivot'!C6 -> 0.063380282 | J3: ='Java Pivot'!D6 -> 0.1584507 | K3: ='Java Pivot'!E6 -> 0.13028169 | L3: ='Java Pivot'!F6 -> 0.095070423 | M3: ='Java Pivot'!G6 -> 0.25352113 | O3: ='JavaScript Pivot'!B6 -> gemini-2.5-flash | P3: ='JavaScript Pivot'!C6 -> 0.077464789 | Q3: ='JavaScript Pivot'!D6 -> 0.1443662 | R3: ='JavaScript Pivot'!E6 -> 0.15140845 | S3: ='JavaScript Pivot'!F6 -> 0.1584507 | T3: ='JavaScript Pivot'!G6 -> 0.31690141
A4: ='Python Pivot'!B8 -> gpt-3.5-turbo | B4: ='Python Pivot'!C8 -> 0.024647887 | C4: ='Python Pivot'!D8 -> 0.024647887 | D4: ='Python Pivot'!E8 -> 0.024647887 | E4: ='Python Pivot'!F8 -> 0.024647887 | F4: ='Python Pivot'!G8 -> 0.059859155 | H4: ='Java Pivot'!B7 -> gpt-3.5-turbo | I4: ='Java Pivot'!C7 -> 0.024647887 | J4: ='Java Pivot'!D7 -> 0.024647887 | K4: ='Java Pivot'!E7 -> 0.024647887 | L4: ='Java Pivot'!F7 -> 0.024647887 | M4: ='Java Pivot'!G7 -> 0.017605634 | O4: ='JavaScript Pivot'!B7 -> gpt-3.5-turbo | P4: ='JavaScript Pivot'!C7 -> 0.024647887 | Q4: ='JavaScript Pivot'!D7 -> 0.021126761 | R4: ='JavaScript Pivot'!E7 -> 0.024647887 | S4: ='JavaScript Pivot'!F7 -> 0.024647887 | T4: ='JavaScript Pivot'!G7 -> 0.038732394
A5: ='Python Pivot'!B7 -> gpt-5 | B5: ='Python Pivot'!C7 -> 0.16197183 | C5: ='Python Pivot'!D7 -> 0.27112676 | D5: ='Python Pivot'!E7 -> 0.41197183 | E5: ='Python Pivot'!F7 -> 0.33802817 | F5: ='Python Pivot'!G7 -> 0.43309859 | H5: ='Java Pivot'!B8 -> gpt-5 | I5: ='Java Pivot'!C8 -> 0.052816901 | J5: ='Java Pivot'!D8 -> 0.18309859 | K5: ='Java Pivot'!E8 -> 0.24295775 | L5: ='Java Pivot'!F8 -> 0.26408451 | M5: ='Java Pivot'!G8 -> 0.45774648 | O5: ='JavaScript Pivot'!B8 -> gpt-5 | P5: ='JavaScript Pivot'!C8 -> 0.16197183 | Q5: ='JavaScript Pivot'!D8 -> 0.23943662 | R5: ='JavaScript Pivot'!E8 -> 0.38380282 | S5: ='JavaScript Pivot'!F8 -> 0.3943662 | T5: ='JavaScript Pivot'!G8 -> 0.4471831
A6: ='Python Pivot'!B9 -> codellama-13b | B6: ='Python Pivot'!C9 -> 0 | C6: ='Python Pivot'!D9 -> 0 | D6: ='Python Pivot'!E9 -> 0 | E6: ='Python Pivot'!F9 -> 0 | F6: ='Python Pivot'!G9 -> 0.01056338 | H6: ='Java Pivot'!B9 -> codellama-13b | I6: ='Java Pivot'!C9 -> 0 | J6: ='Java Pivot'!D9 -> 0 | K6: ='Java Pivot'!E9 -> 0 | L6: ='Java Pivot'!F9 -> 0 | M6: ='Java Pivot'!G9 -> 0.007042254 | O6: ='JavaScript Pivot'!B9 -> codellama-13b | P6: ='JavaScript Pivot'!C9 -> 0 | Q6: ='JavaScript Pivot'!D9 -> 0 | R6: ='JavaScript Pivot'!E9 -> 0 | S6: ='JavaScript Pivot'!F9 -> 0 | T6: ='JavaScript Pivot'!G9 -> 0.0035211268
A7: ='Python Pivot'!B10 -> codellama-34b | B7: ='Python Pivot'!C10 -> 0 | C7: ='Python Pivot'!D10 -> 0 | D7: ='Python Pivot'!E10 -> 0 | E7: ='Python Pivot'!F10 -> 0 | F7: ='Python Pivot'!G10 -> 0 | H7: ='Python Pivot'!M10 -> 0 | I7: ='Python Pivot'!N10 -> 0 | J7: ='Python Pivot'!O10 -> 0 | K7: ='Python Pivot'!P10 -> 0 | L7: ='Python Pivot'!Q10 -> 0 | M7: ='Python Pivot'!R10 -> 0 | O7: ='JavaScript Pivot'!B10 -> codellama-34b | P7: ='JavaScript Pivot'!C10 -> 0 | Q7: ='JavaScript Pivot'!D10 -> 0 | R7: ='JavaScript Pivot'!E10 -> 0 | S7: ='JavaScript Pivot'!F10 -> 0 | T7: ='JavaScript Pivot'!G10 -> 0
A8: CodeLlama-70B | B8: 0 | C8: 0 | D8: 0 | E8: 0 | F8: 0 | H8: CodeLlama-70B | I8: 0 | J8: 0 | K8: 0 | L8: 0 | M8: 0 | O8: CodeLlama-70B | P8: 0 | Q8: 0 | R8: 0 | S8: 0 | T8: 0
A9: ='Python Pivot'!B11 -> deepseek-coder-33b | B9: ='Python Pivot'!C11 -> 0 | C9: ='Python Pivot'!D11 -> 0 | D9: ='Python Pivot'!E11 -> 0 | E9: ='Python Pivot'!F11 -> 0 | F9: ='Python Pivot'!G11 -> 0.031690141 | H9: ='Java Pivot'!B10 -> deepseek-coder-33b | I9: ='Java Pivot'!C10 -> 0 | J9: ='Java Pivot'!D10 -> 0 | K9: ='Java Pivot'!E10 -> 0 | L9: ='Java Pivot'!F10 -> 0 | M9: ='Java Pivot'!G10 -> 0.017605634 | O9: ='JavaScript Pivot'!B11 -> deepseek-coder-33b | P9: ='JavaScript Pivot'!C11 -> 0 | Q9: ='JavaScript Pivot'!D11 -> 0 | R9: ='JavaScript Pivot'!E11 -> 0 | S9: ='JavaScript Pivot'!F11 -> 0 | T9: ='JavaScript Pivot'!G11 -> 0.028169014
A10: ='Python Pivot'!B12 -> deepseek-coder-6.7b | B10: ='Python Pivot'!C12 -> 0 | C10: ='Python Pivot'!D12 -> 0 | D10: ='Python Pivot'!E12 -> 0 | E10: ='Python Pivot'!F12 -> 0 | F10: ='Python Pivot'!G12 -> 0.0035211268 | H10: ='Java Pivot'!B11 -> deepseek-coder-6.7b | I10: ='Java Pivot'!C11 -> 0 | J10: ='Java Pivot'!D11 -> 0 | K10: ='Java Pivot'!E11 -> 0 | L10: ='Java Pivot'!F11 -> 0 | M10: ='Java Pivot'!G11 -> 0.003521127 | O10: ='JavaScript Pivot'!B12 -> deepseek-coder-6.7b | P10: ='JavaScript Pivot'!C12 -> 0 | Q10: ='JavaScript Pivot'!D12 -> 0 | R10: ='JavaScript Pivot'!E12 -> 0 | S10: ='JavaScript Pivot'!F12 -> 0 | T10: ='JavaScript Pivot'!G12 -> 0.021126761
A11: ='Python Pivot'!B13 -> gemma3-12b | B11: ='Python Pivot'!C13 -> 0.031690141 | C11: ='Python Pivot'!D13 -> 0.01056338 | D11: ='Python Pivot'!E13 -> 0.0035211268 | E11: ='Python Pivot'!F13 -> 0.024647887 | F11: ='Python Pivot'!G13 -> 0.066901408 | H11: ='Java Pivot'!B12 -> gemma3-12b | I11: ='Java Pivot'!C12 -> 0.021126761 | J11: ='Java Pivot'!D12 -> 0.021126761 | K11: ='Java Pivot'!E12 -> 0.003521127 | L11: ='Java Pivot'!F12 -> 0.024647887 | M11: ='Java Pivot'!G12 -> 0.014084507 | O11: ='JavaScript Pivot'!B13 -> gemma3-12b | P11: ='JavaScript Pivot'!C13 -> 0.035211268 | Q11: ='JavaScript Pivot'!D13 -> 0.059859155 | R11: ='JavaScript Pivot'!E13 -> 0.01056338 | S11: ='JavaScript Pivot'!F13 -> 0 | T11: ='JavaScript Pivot'!G13 -> 0.13380282
A12: ='Python Pivot'!B14 -> gemma3-27b | B12: ='Python Pivot'!C14 -> 0.014084507 | C12: ='Python Pivot'!D14 -> 0.024647887 | D12: ='Python Pivot'!E14 -> 0.014084507 | E12: ='Python Pivot'!F14 -> 0.024647887 | F12: ='Python Pivot'!G14 -> 0.10915493 | H12: ='Java Pivot'!B13 -> gemma3-27b | I12: ='Java Pivot'!C13 -> 0.028169014 | J12: ='Java Pivot'!D13 -> 0.017605634 | K12: ='Java Pivot'!E13 -> 0.031690141 | L12: ='Java Pivot'!F13 -> 0.045774648 | M12: ='Java Pivot'!G13 -> 0.066901408 | O12: ='JavaScript Pivot'!B14 -> gemma3-27b | P12: ='JavaScript Pivot'!C14 -> 0.070422535 | Q12: ='JavaScript Pivot'!D14 -> 0.049295775 | R12: ='JavaScript Pivot'!E14 -> 0.035211268 | S12: ='JavaScript Pivot'!F14 -> 0.024647887 | T12: ='JavaScript Pivot'!G14 -> 0.14084507
A13: ='Python Pivot'!B15 -> gpt-oss-20b | B13: ='Python Pivot'!C15 -> 0.056338028 | C13: ='Python Pivot'!D15 -> 0.052816901 | D13: ='Python Pivot'!E15 -> 0.017605634 | E13: ='Python Pivot'!F15 -> 0.024647887 | F13: ='Python Pivot'!G15 -> 0.1443662 | H13: ='Java Pivot'!B14 -> gpt-oss-20b | I13: ='Java Pivot'!C14 -> 0.031690141 | J13: ='Java Pivot'!D14 -> 0.063380282 | K13: ='Java Pivot'!E14 -> 0.077464789 | L13: ='Java Pivot'!F14 -> 0.066901408 | M13: ='Java Pivot'!G14 -> 0.088028169 | O13: ='JavaScript Pivot'!B15 -> gpt-oss-20b | P13: ='JavaScript Pivot'!C15 -> 0.056338028 | Q13: ='JavaScript Pivot'!D15 -> 0.10915493 | R13: ='JavaScript Pivot'!E15 -> 0.073943662 | S13: ='JavaScript Pivot'!F15 -> 0.095070423 | T13: ='JavaScript Pivot'!G15 -> 0.080985915
A14: ='Python Pivot'!B16 -> llama3.1-8b | B14: ='Python Pivot'!C16 -> 0.014084507 | C14: ='Python Pivot'!D16 -> 0 | D14: ='Python Pivot'!E16 -> 0.0070422535 | E14: ='Python Pivot'!F16 -> 0.0035211268 | F14: ='Python Pivot'!G16 -> 0 | H14: ='Java Pivot'!B15 -> llama3.1-8b | I14: ='Java Pivot'!C15 -> 0.007042254 | J14: ='Java Pivot'!D15 -> 0.007042254 | K14: ='Java Pivot'!E15 -> 0.007042254 | L14: ='Java Pivot'!F15 -> 0.003521127 | M14: ='Java Pivot'!G15 -> 0.007042254 | O14: ='JavaScript Pivot'!B16 -> llama3.1-8b | P14: ='JavaScript Pivot'!C16 -> 0.0035211268 | Q14: ='JavaScript Pivot'!D16 -> 0 | R14: ='JavaScript Pivot'!E16 -> 0.021126761 | S14: ='JavaScript Pivot'!F16 -> 0.014084507 | T14: ='JavaScript Pivot'!G16 -> 0.0035211268
A15: ='Python Pivot'!B17 -> llama3.3-70b | B15: ='Python Pivot'!C17 -> 0.024647887 | C15: ='Python Pivot'!D17 -> 0.10211268 | D15: ='Python Pivot'!E17 -> 0.017605634 | E15: ='Python Pivot'!F17 -> 0.017605634 | F15: ='Python Pivot'!G17 -> 0.059859155 | H15: ='Java Pivot'!B16 -> llama3.3-70b | I15: ='Java Pivot'!C16 -> 0.003521127 | J15: ='Java Pivot'!D16 -> 0 | K15: ='Java Pivot'!E16 -> 0.003521127 | L15: ='Java Pivot'!F16 -> 0.017605634 | M15: ='Java Pivot'!G16 -> 0.049295775 | O15: ='JavaScript Pivot'!B17 -> llama3.3-70b | P15: ='JavaScript Pivot'!C17 -> 0.11267606 | Q15: ='JavaScript Pivot'!D17 -> 0.13380282 | R15: ='JavaScript Pivot'!E17 -> 0.11619718 | S15: ='JavaScript Pivot'!F17 -> 0.20070423 | T15: ='JavaScript Pivot'!G17 -> 0.13380282
A16: ='Python Pivot'!B18 -> phi4-14b | B16: ='Python Pivot'!C18 -> 0 | C16: ='Python Pivot'!D18 -> 0.049295775 | D16: ='Python Pivot'!E18 -> 0 | E16: ='Python Pivot'!F18 -> 0.021126761 | F16: ='Python Pivot'!G18 -> 0.12676056 | H16: ='Java Pivot'!B17 -> phi4-14b | I16: ='Java Pivot'!C17 -> 0.01056338 | J16: ='Java Pivot'!D17 -> 0.049295775 | K16: ='Java Pivot'!E17 -> 0.01056338 | L16: ='Java Pivot'!F17 -> 0.024647887 | M16: ='Java Pivot'!G17 -> 0.024647887 | O16: ='JavaScript Pivot'!B18 -> phi4-14b | P16: ='JavaScript Pivot'!C18 -> 0.052816901 | Q16: ='JavaScript Pivot'!D18 -> 0.098591549 | R16: ='JavaScript Pivot'!E18 -> 0.080985915 | S16: ='JavaScript Pivot'!F18 -> 0.14084507 | T16: ='JavaScript Pivot'!G18 -> 0.11619718
A17: ='Python Pivot'!B19 -> qwen2.5-coder-14b | B17: ='Python Pivot'!C19 -> 0 | C17: ='Python Pivot'!D19 -> 0 | D17: ='Python Pivot'!E19 -> 0 | E17: ='Python Pivot'!F19 -> 0 | F17: ='Python Pivot'!G19 -> 0.0035211268 | H17: ='Java Pivot'!B18 -> qwen2.5-coder-14b | I17: ='Java Pivot'!C18 -> 0 | J17: ='Java Pivot'!D18 -> 0 | K17: ='Java Pivot'!E18 -> 0 | L17: ='Java Pivot'!F18 -> 0 | M17: ='Java Pivot'!G18 -> 0 | O17: ='JavaScript Pivot'!B19 -> qwen2.5-coder-14b | P17: ='JavaScript Pivot'!C19 -> 0 | Q17: ='JavaScript Pivot'!D19 -> 0 | R17: ='JavaScript Pivot'!E19 -> 0 | S17: ='JavaScript Pivot'!F19 -> 0 | T17: ='JavaScript Pivot'!G19 -> 0.088028169
A18: ='Python Pivot'!B20 -> qwen2.5-coder-32b | B18: ='Python Pivot'!C20 -> 0 | C18: ='Python Pivot'!D20 -> 0 | D18: ='Python Pivot'!E20 -> 0 | E18: ='Python Pivot'!F20 -> 0 | F18: ='Python Pivot'!G20 -> 0.088028169 | H18: ='Java Pivot'!B19 -> qwen2.5-coder-32b | I18: ='Java Pivot'!C19 -> 0 | J18: ='Java Pivot'!D19 -> 0 | K18: ='Java Pivot'!E19 -> 0 | L18: ='Java Pivot'!F19 -> 0 | M18: ='Java Pivot'!G19 -> 0.042253521 | O18: ='JavaScript Pivot'!B20 -> qwen2.5-coder-32b | P18: ='JavaScript Pivot'!C20 -> 0 | Q18: ='JavaScript Pivot'!D20 -> 0 | R18: ='JavaScript Pivot'!E20 -> 0 | S18: ='JavaScript Pivot'!F20 -> 0 | T18: ='JavaScript Pivot'!G20 -> 0.095070423
A19: ='Python Pivot'!B21 -> qwen3-14b | B19: ='Python Pivot'!C21 -> 0 | C19: ='Python Pivot'!D21 -> 0.021126761 | D19: ='Python Pivot'!E21 -> 0.01056338 | E19: ='Python Pivot'!F21 -> 0.031690141 | F19: ='Python Pivot'!G21 -> 0.052816901 | H19: ='Java Pivot'!B20 -> qwen3-14b | I19: ='Java Pivot'!C20 -> 0.014084507 | J19: ='Java Pivot'!D20 -> 0.031690141 | K19: ='Java Pivot'!E20 -> 0.007042254 | L19: ='Java Pivot'!F20 -> 0.01056338 | M19: ='Java Pivot'!G20 -> 0.014084507 | O19: ='JavaScript Pivot'!B21 -> qwen3-14b | P19: ='JavaScript Pivot'!C21 -> 0.052816901 | Q19: ='JavaScript Pivot'!D21 -> 0.031690141 | R19: ='JavaScript Pivot'!E21 -> 0.038732394 | S19: ='JavaScript Pivot'!F21 -> 0.0070422535 | T19: ='JavaScript Pivot'!G21 -> 0.024647887
A20: ='Python Pivot'!B22 -> qwen3-30b | B20: ='Python Pivot'!C22 -> 0.045774648 | C20: ='Python Pivot'!D22 -> 0.038732394 | D20: ='Python Pivot'!E22 -> 0.088028169 | E20: ='Python Pivot'!F22 -> 0.063380282 | F20: ='Python Pivot'!G22 -> 0.15140845 | H20: ='Java Pivot'!B21 -> qwen3-30b | I20: ='Java Pivot'!C21 -> 0.045774648 | J20: ='Java Pivot'!D21 -> 0.052816901 | K20: ='Java Pivot'!E21 -> 0.052816901 | L20: ='Java Pivot'!F21 -> 0.003521127 | M20: ='Java Pivot'!G21 -> 0.049295775 | O20: ='JavaScript Pivot'!B22 -> qwen3-30b | P20: ='JavaScript Pivot'!C22 -> 0.049295775 | Q20: ='JavaScript Pivot'!D22 -> 0.028169014 | R20: ='JavaScript Pivot'!E22 -> 0.070422535 | S20: ='JavaScript Pivot'!F22 -> 0.059859155 | T20: ='JavaScript Pivot'!G22 -> 0.077464789
B21: =AVERAGE(B3:B5,B11:B16,B19:B20) -> 0.040973111 | C21: =AVERAGE(C3:C5,C11:C16,C19:C20) -> 0.072023047 | D21: =AVERAGE(D3:D5,D11:D16,D19:D20) -> 0.065620999 | E21: =AVERAGE(E3:E5,E11:E16,E19:E20) -> 0.069462228 | F21: =AVERAGE(F3:F20) -> 0.08470266 | I21: =AVERAGE(I3:I5,I11:I16,I19:I20) -> 0.027528809 | J21: =AVERAGE(J3:J5,J11:J16,J19:J20) -> 0.055377721 | K21: =AVERAGE(K3:K5,K11:K16,K19:K20) -> 0.053777209 | L21: =AVERAGE(L3:L5,L11:L16,L19:L20) -> 0.052816901 | M21: =AVERAGE(M3:M20) -> 0.061815337 | P21: =AVERAGE(P3:P5,P11:P16,P19:P20) -> 0.063380282 | Q21: =AVERAGE(Q3:Q5,Q11:Q16,Q19:Q20) -> 0.083226633 | R21: =AVERAGE(R3:R5,R11:R16,R19:R20) -> 0.091549296 | S21: =AVERAGE(S3:S5,S11:S16,S19:S20) -> 0.10179257 | T21: =AVERAGE(T3:T20) -> 0.097222222
B24: Cascade | D24: E2E
B25: 1 | C25: 2 | D25: 1 | E25: 2 | F25: 3 | G25: All Avg.
A26: Gemini 2.5-flash | B26: =(B3+I3+P3)/3 -> 0.072769953 | C26: =(C3+J3+Q3)/3 -> 0.16666667 | D26: =(D3+K3+R3)/3 -> 0.13615023 | E26: =(E3+L3+S3)/3 -> 0.14788732 | F26: =(F3+M3+T3)/3 -> 0.25117371 | G26: =AVERAGE(B26:F26) -> 0.15492958 | K26: Model | L26: Cascade (Level 1) Python | M26: Cascade (Level 1) Java | N26: Cascade (Level 1) JavaScript | O26: End-to-End (Level 1) Python | P26: End-to-End (Level 1) Java | Q26: End-to-End (Level 1) JavaScript | R26: All Avg.
A27: GPT-3.5-turbo | B27: =(B4+I4+P4)/3 -> 0.024647887 | C27: =(C4+J4+Q4)/3 -> 0.023474178 | D27: =(D4+K4+R4)/3 -> 0.024647887 | E27: =(E4+L4+S4)/3 -> 0.024647887 | F27: =(F4+M4+T4)/3 -> 0.038732394 | G27: =AVERAGE(B27:F27) -> 0.027230047 | K27: Gemini 2.5-flash | L27: =B3 -> 0.077464789 | M27: =I3 -> 0.063380282 | N27: =P3 -> 0.077464789 | O27: =C3 -> 0.1971831 | P27: =J3 -> 0.1584507 | Q27: =Q3 -> 0.1443662 | R27: =AVERAGE(L27:Q27) -> 0.11971831
A28: GPT-5 | B28: =(B5+I5+P5)/3 -> 0.12558685 | C28: =(C5+J5+Q5)/3 -> 0.23122066 | D28: =(D5+K5+R5)/3 -> 0.34624413 | E28: =(E5+L5+S5)/3 -> 0.33215962 | F28: =(F5+M5+T5)/3 -> 0.44600939 | G28: =AVERAGE(B28:F28) -> 0.29624413 | K28: GPT-3.5-turbo | L28: =B4 -> 0.024647887 | M28: =I4 -> 0.024647887 | N28: =P4 -> 0.024647887 | O28: =C4 -> 0.024647887 | P28: =J4 -> 0.024647887 | Q28: =Q4 -> 0.021126761 | R28: =AVERAGE(L28:Q28) -> 0.024061033
A29: CodeLlama-13B | B29: =(B6+I6+P6)/3 -> 0 | C29: =(C6+J6+Q6)/3 -> 0 | D29: =(D6+K6+R6)/3 -> 0 | E29: =(E6+L6+S6)/3 -> 0 | F29: =(F6+M6+T6)/3 -> 0.0070422537 | G29: =AVERAGE(B29:F29) -> 0.0014084507 | K29: GPT-5 | L29: =B5 -> 0.16197183 | M29: =I5 -> 0.052816901 | N29: =P5 -> 0.16197183 | O29: =C5 -> 0.27112676 | P29: =J5 -> 0.18309859 | Q29: =Q5 -> 0.23943662 | R29: =AVERAGE(L29:Q29) -> 0.17840376
A30: CodeLlama-34B | B30: =(B7+I7+P7)/3 -> 0 | C30: =(C7+J7+Q7)/3 -> 0 | D30: =(D7+K7+R7)/3 -> 0 | E30: =(E7+L7+S7)/3 -> 0 | F30: =(F7+M7+T7)/3 -> 0 | G30: =AVERAGE(B30:F30) -> 0 | K30: Gemma-3-12B | L30: =B11 -> 0.031690141 | M30: =I11 -> 0.021126761 | N30: =P11 -> 0.035211268 | O30: =C11 -> 0.01056338 | P30: =J11 -> 0.021126761 | Q30: =Q11 -> 0.059859155 | R30: =AVERAGE(L30:Q30) -> 0.029929578
A31: CodeLlama-70B | B31: =(B8+I8+P8)/3 -> 0 | C31: =(C8+J8+Q8)/3 -> 0 | D31: =(D8+K8+R8)/3 -> 0 | E31: =(E8+L8+S8)/3 -> 0 | F31: =(F8+M8+T8)/3 -> 0 | G31: =AVERAGE(B31:F31) -> 0 | K31: Gemma-3-27B | L31: =B12 -> 0.014084507 | M31: =I12 -> 0.028169014 | N31: =P12 -> 0.070422535 | O31: =C12 -> 0.024647887 | P31: =J12 -> 0.017605634 | Q31: =Q12 -> 0.049295775 | R31: =AVERAGE(L31:Q31) -> 0.034037559
A32: DeepSeek-Coder-33B | B32: =(B9+I9+P9)/3 -> 0 | C32: =(C9+J9+Q9)/3 -> 0 | D32: =(D9+K9+R9)/3 -> 0 | E32: =(E9+L9+S9)/3 -> 0 | F32: =(F9+M9+T9)/3 -> 0.025821596 | G32: =AVERAGE(B32:F32) -> 0.0051643193 | K32: GPT-oss-20B | L32: =B13 -> 0.056338028 | M32: =I13 -> 0.031690141 | N32: =P13 -> 0.056338028 | O32: =C13 -> 0.052816901 | P32: =J13 -> 0.063380282 | Q32: =Q13 -> 0.10915493 | R32: =AVERAGE(L32:Q32) -> 0.061619718
A33: DeepSeek-Coder-6.7B | B33: =(B10+I10+P10)/3 -> 0 | C33: =(C10+J10+Q10)/3 -> 0 | D33: =(D10+K10+R10)/3 -> 0 | E33: =(E10+L10+S10)/3 -> 0 | F33: =(F10+M10+T10)/3 -> 0.0093896714 | G33: =AVERAGE(B33:F33) -> 0.0018779343 | K33: Llama3.1-8B | L33: =B14 -> 0.014084507 | M33: =I14 -> 0.007042254 | N33: =P14 -> 0.0035211268 | O33: =C14 -> 0 | P33: =J14 -> 0.007042254 | Q33: =Q14 -> 0 | R33: =AVERAGE(L33:Q33) -> 0.0052816903
A34: Gemma-3-12B | B34: =(B11+I11+P11)/3 -> 0.029342723 | C34: =(C11+J11+Q11)/3 -> 0.030516432 | D34: =(D11+K11+R11)/3 -> 0.0058685447 | E34: =(E11+L11+S11)/3 -> 0.016431925 | F34: =(F11+M11+T11)/3 -> 0.071596244 | G34: =AVERAGE(B34:F34) -> 0.030751174 | K34: Llama3.3-70B | L34: =B15 -> 0.024647887 | M34: =I15 -> 0.003521127 | N34: =P15 -> 0.11267606 | O34: =C15 -> 0.10211268 | P34: =J15 -> 0 | Q34: =Q15 -> 0.13380282 | R34: =AVERAGE(L34:Q34) -> 0.062793427
A35: Gemma-3-27B | B35: =(B12+I12+P12)/3 -> 0.037558685 | C35: =(C12+J12+Q12)/3 -> 0.030516432 | D35: =(D12+K12+R12)/3 -> 0.026995305 | E35: =(E12+L12+S12)/3 -> 0.031690141 | F35: =(F12+M12+T12)/3 -> 0.1056338 | G35: =AVERAGE(B35:F35) -> 0.046478873 | K35: Phi4-14B | L35: =B16 -> 0 | M35: =I16 -> 0.01056338 | N35: =P16 -> 0.052816901 | O35: =C16 -> 0.049295775 | P35: =J16 -> 0.049295775 | Q35: =Q16 -> 0.098591549 | R35: =AVERAGE(L35:Q35) -> 0.04342723
A36: GPT-oss-20B | B36: =(B13+I13+P13)/3 -> 0.048122066 | C36: =(C13+J13+Q13)/3 -> 0.075117371 | D36: =(D13+K13+R13)/3 -> 0.056338028 | E36: =(E13+L13+S13)/3 -> 0.062206573 | F36: =(F13+M13+T13)/3 -> 0.10446009 | G36: =AVERAGE(B36:F36) -> 0.069248826 | K36: Qwen3-14B | L36: =B19 -> 0 | M36: =I19 -> 0.014084507 | N36: =P19 -> 0.052816901 | O36: =C19 -> 0.021126761 | P36: =J19 -> 0.031690141 | Q36: =Q19 -> 0.031690141 | R36: =AVERAGE(L36:Q36) -> 0.025234742
A37: Llama3.1-8B | B37: =(B14+I14+P14)/3 -> 0.0082159626 | C37: =(C14+J14+Q14)/3 -> 0.002347418 | D37: =(D14+K14+R14)/3 -> 0.011737089 | E37: =(E14+L14+S14)/3 -> 0.0070422536 | F37: =(F14+M14+T14)/3 -> 0.0035211269 | G37: =AVERAGE(B37:F37) -> 0.0065727701 | K37: Qwen3-30B | L37: =B20 -> 0.045774648 | M37: =I20 -> 0.045774648 | N37: =P20 -> 0.049295775 | O37: =C20 -> 0.038732394 | P37: =J20 -> 0.052816901 | Q37: =Q20 -> 0.028169014 | R37: =AVERAGE(L37:Q37) -> 0.04342723
A38: Llama3.3-70B | B38: =(B15+I15+P15)/3 -> 0.046948357 | C38: =(C15+J15+Q15)/3 -> 0.078638498 | D38: =(D15+K15+R15)/3 -> 0.045774648 | E38: =(E15+L15+S15)/3 -> 0.078638498 | F38: =(F15+M15+T15)/3 -> 0.080985916 | G38: =AVERAGE(B38:F38) -> 0.066197183 | K38: All Avg. | L38: =AVERAGE(L27:L37) -> 0.040973111 | M38: =AVERAGE(M27:M37) -> 0.027528809 | N38: =AVERAGE(N27:N37) -> 0.063380282 | O38: =AVERAGE(O27:O37) -> 0.072023047 | P38: =AVERAGE(P27:P37) -> 0.055377721 | Q38: =AVERAGE(Q27:Q37) -> 0.083226633 | R38: =AVERAGE(L27:Q37) -> 0.057084934
A39: Phi4-14B | B39: =(B16+I16+P16)/3 -> 0.02112676 | C39: =(C16+J16+Q16)/3 -> 0.0657277 | D39: =(D16+K16+R16)/3 -> 0.030516432 | E39: =(E16+L16+S16)/3 -> 0.062206573 | F39: =(F16+M16+T16)/3 -> 0.089201878 | G39: =AVERAGE(B39:F39) -> 0.053755868
A40: Qwen2.5-Coder-14B | B40: =(B17+I17+P17)/3 -> 0 | C40: =(C17+J17+Q17)/3 -> 0 | D40: =(D17+K17+R17)/3 -> 0 | E40: =(E17+L17+S17)/3 -> 0 | F40: =(F17+M17+T17)/3 -> 0.030516432 | G40: =AVERAGE(B40:F40) -> 0.0061032864
A41: Qwen2.5-Coder-32B | B41: =(B18+I18+P18)/3 -> 0 | C41: =(C18+J18+Q18)/3 -> 0 | D41: =(D18+K18+R18)/3 -> 0 | E41: =(E18+L18+S18)/3 -> 0 | F41: =(F18+M18+T18)/3 -> 0.075117371 | G41: =AVERAGE(B41:F41) -> 0.015023474
A42: Qwen3-14B | B42: =(B19+I19+P19)/3 -> 0.022300469 | C42: =(C19+J19+Q19)/3 -> 0.028169014 | D42: =(D19+K19+R19)/3 -> 0.018779343 | E42: =(E19+L19+S19)/3 -> 0.016431925 | F42: =(F19+M19+T19)/3 -> 0.030516432 | G42: =AVERAGE(B42:F42) -> 0.023239437
...

Sheet Python Pivot
A3: 平均值项:score | C3: level | D3: mode
C4: 1 | E4: 2 | G4: 3 | H4: 总计
A5: source | B5: model | C5: cascade | D5: direct | E5: cascade | F5: direct | G5: direct
A6: close | B6: gemini-2.5-flash | C6: 0.077464789 | D6: 0.1971831 | E6: 0.12676056 | F6: 0.19014085 | G6: 0.18309859 | H6: 0.15492958
B7: gpt-5 | C7: 0.16197183 | D7: 0.27112676 | E7: 0.41197183 | F7: 0.33802817 | G7: 0.43309859 | H7: 0.32323944
B8: gpt-3.5-turbo | C8: 0.024647887 | D8: 0.024647887 | E8: 0.024647887 | F8: 0.024647887 | G8: 0.059859155 | H8: 0.031690141
A9: open | B9: codellama-13b | G9: 0.01056338 | H9: 0.01056338
B10: codellama-34b | G10: 0 | H10: 0
B11: deepseek-coder-33b | G11: 0.031690141 | H11: 0.031690141
B12: deepseek-coder-6.7b | G12: 0.0035211268 | H12: 0.0035211268
B13: gemma3-12b | C13: 0.031690141 | D13: 0.01056338 | E13: 0.0035211268 | F13: 0.024647887 | G13: 0.066901408 | H13: 0.027464789
B14: gemma3-27b | C14: 0.014084507 | D14: 0.024647887 | E14: 0.014084507 | F14: 0.024647887 | G14: 0.10915493 | H14: 0.037323944
B15: gpt-oss-20b | C15: 0.056338028 | D15: 0.052816901 | E15: 0.017605634 | F15: 0.024647887 | G15: 0.1443662 | H15: 0.05915493
B16: llama3.1-8b | C16: 0.014084507 | D16: 0 | E16: 0.0070422535 | F16: 0.0035211268 | G16: 0 | H16: 0.0049295775
B17: llama3.3-70b | C17: 0.024647887 | D17: 0.10211268 | E17: 0.017605634 | F17: 0.017605634 | G17: 0.059859155 | H17: 0.044366197
B18: phi4-14b | D18: 0.049295775 | E18: 0 | F18: 0.021126761 | G18: 0.12676056 | H18: 0.049295775
B19: qwen2.5-coder-14b | G19: 0.0035211268 | H19: 0.0035211268
B20: qwen2.5-coder-32b | G20: 0.088028169 | H20: 0.088028169
B21: qwen3-14b | C21: 0 | D21: 0.021126761 | E21: 0.01056338 | F21: 0.031690141 | G21: 0.052816901 | H21: 0.023239437
B22: qwen3-30b | C22: 0.045774648 | D22: 0.038732394 | E22: 0.088028169 | F22: 0.063380282 | G22: 0.15140845 | H22: 0.077464789
A23: 总计 | C23: 0.045070423 | D23: 0.072023047 | E23: 0.065620999 | F23: 0.069462228 | G23: 0.08968517 | H23: 0.070892019

Sheet Python
A1: date | B1: model | C1: mode | D1: timestamp | E1: level | F1: passed | G1: failed | H1: executed | I1: score | J1: source
A2: 20251024-1-python | B2: codellama-13b | C2: direct | D2: 20251027-124148 | E2: 3 | F2: 3 | G2: 281 | H2: 23 | I2: 0.01056338 | J2: open
A3: 20251024-1-python | B3: codellama-34b | C3: direct | D3: 20251027-120902 | E3: 3 | F3: 0 | G3: 284 | H3: 0 | I3: 0 | J3: open
A4: 20251024-1-python | B4: deepseek-coder-33b | C4: direct | D4: 20251027-125123 | E4: 3 | F4: 9 | G4: 275 | H4: 98 | I4: 0.031690141 | J4: open
A5: 20251024-1-python | B5: deepseek-coder-6.7b | C5: direct | D5: 20251027-131027 | E5: 3 | F5: 1 | G5: 283 | H5: 25 | I5: 0.0035211268 | J5: open
A6: 20251024-1-python | B6: gemma3-12b | C6: cascade | D6: 20251024-131206 | E6: 1 | F6: 9 | G6: 275 | H6: 37 | I6: 0.031690141 | J6: open
A7: 20251024-1-python | B7: gemma3-12b | C7: cascade | D7: 20251024-152512 | E7: 2 | F7: 1 | G7: 283 | H7: 6 | I7: 0.0035211268 | J7: open
A8: 20251024-1-python | B8: gemma3-12b | C8: direct | D8: 20251025-035647 | E8: 1 | F8: 3 | G8: 281 | H8: 31 | I8: 0.01056338 | J8: open
A9: 20251024-1-python | B9: gemma3-12b | C9: direct | D9: 20251026-000440 | E9: 2 | F9: 7 | G9: 277 | H9: 37 | I9: 0.024647887 | J9: open
A10: 20251024-1-python | B10: gemma3-12b | C10: direct | D10: 20251026-124526 | E10: 3 | F10: 19 | G10: 265 | H10: 152 | I10: 0.066901408 | J10: open
A11: 20251024-1-python | B11: gemma3-27b | C11: cascade | D11: 20251024-164054 | E11: 1 | F11: 4 | G11: 280 | H11: 27 | I11: 0.014084507 | J11: open
A12: 20251024-1-python | B12: gemma3-27b | C12: cascade | D12: 20251024-191431 | E12: 2 | F12: 4 | G12: 280 | H12: 28 | I12: 0.014084507 | J12: open
A13: 20251024-1-python | B13: gemma3-27b | C13: direct | D13: 20251026-153202 | E13: 1 | F13: 7 | G13: 277 | H13: 37 | I13: 0.024647887 | J13: open
... A61: pyclosesources | B61: gpt-5 | C61: direct | D61: 20251030-183910 | E61: 3 | F61: 123 | G61: 161 | H61: 266 | I61: 0.43309859 | J61: close

Sheet Java Pivot
A3: 平均值项:score | C3: level | D3: mode
C4: 1 | E4: 2 | G4: 3 | H4: 总计
A5: source | B5: model | C5: cascade | D5: direct | E5: cascade | F5: direct | G5: direct
A6: close | B6: gemini-2.5-flash | C6: 0.063380282 | D6: 0.1584507 | E6: 0.13028169 | F6: 0.095070423 | G6: 0.25352113 | H6: 0.14014085
B7: gpt-3.5-turbo | C7: 0.024647887 | D7: 0.024647887 | E7: 0.024647887 | F7: 0.024647887 | G7: 0.017605634 | H7: 0.023239436
B8: gpt-5 | C8: 0.052816901 | D8: 0.18309859 | E8: 0.24295775 | F8: 0.26408451 | G8: 0.45774648 | H8: 0.24014085
A9: open | B9: codellama-13b | G9: 0.007042254 | H9: 0.007042254
B10: deepseek-coder-33b | G10: 0.017605634 | H10: 0.017605634
B11: deepseek-coder-6.7b | G11: 0.003521127 | H11: 0.003521127
B12: gemma3-12b | C12: 0.021126761 | D12: 0.021126761 | E12: 0.003521127 | F12: 0.024647887 | G12: 0.014084507 | H12: 0.016901409
B13: gemma3-27b | C13: 0.028169014 | D13: 0.017605634 | E13: 0.031690141 | F13: 0.045774648 | G13: 0.066901408 | H13: 0.038028169
B14: gpt-oss-20b | C14: 0.031690141 | D14: 0.063380282 | E14: 0.077464789 | F14: 0.066901408 | G14: 0.088028169 | H14: 0.065492958
B15: llama3.1-8b | C15: 0.007042254 | D15: 0.007042254 | E15: 0.007042254 | F15: 0.003521127 | G15: 0.007042254 | H15: 0.0063380286
B16: llama3.3-70b | C16: 0.003521127 | D16: 0 | E16: 0.003521127 | F16: 0.017605634 | G16: 0.049295775 | H16: 0.014788733
B17: phi4-14b | C17: 0.01056338 | D17: 0.049295775 | E17: 0.01056338 | F17: 0.024647887 | G17: 0.024647887 | H17: 0.023943662
B18: qwen2.5-coder-14b | G18: 0 | H18: 0
B19: qwen2.5-coder-32b | G19: 0.042253521 | H19: 0.042253521
B20: qwen3-14b | C20: 0.014084507 | D20: 0.031690141 | E20: 0.007042254 | F20: 0.01056338 | G20: 0.014084507 | H20: 0.015492958
B21: qwen3-30b | C21: 0.045774648 | D21: 0.052816901 | E21: 0.052816901 | F21: 0.003521127 | G21: 0.049295775 | H21: 0.04084507
A22: 总计 | C22: 0.027528809 | D22: 0.055377721 | E22: 0.053777209 | F22: 0.052816901 | G22: 0.069542254 | H22: 0.053286385

Sheet Java
A1: date | B1: model | C1: mode | D1: timestamp | E1: level | F1: passed | G1: failed | H1: executed | I1: score | J1: source
A2: 20251031-1-javadirect3 | B2: codellama-13b | C2: direct | D2: 20251031-201036 | E2: 3 | F2: 2 | G2: 282 | H2: 15 | I2: 0.007042254 | J2: open
A3: 20251031-1-javadirect3 | B3: deepseek-coder-33b | C3: direct | D3: 20251031-200950 | E3: 3 | F3: 5 | G3: 279 | H3: 41 | I3: 0.017605634 | J3: open
A4: 20251031-1-javadirect3 | B4: deepseek-coder-6.7b | C4: direct | D4: 20251031-202957 | E4: 3 | F4: 1 | G4: 283 | H4: 6 | I4: 0.003521127 | J4: open
A5: 20251029-1-java-opensources | B5: gemma3-12b | C5: cascade | D5: 20251029-141855 | E5: 1 | F5: 6 | G5: 278 | H5: 23 | I5: 0.021126761 | J5: open
A6: 20251029-1-java-opensources | B6: gemma3-12b | C6: cascade | D6: 20251029-172111 | E6: 2 | F6: 1 | G6: 283 | H6: 14 | I6: 0.003521127 | J6: open
A7: 20251029-1-java-opensources | B7: gemma3-12b | C7: direct | D7: 20251029-222906 | E7: 1 | F7: 6 | G7: 278 | H7: 23 | I7: 0.021126761 | J7: open
A8: 20251029-1-java-opensources | B8: gemma3-12b | C8: direct | D8: 20251030-034426 | E8: 2 | F8: 7 | G8: 277 | H8: 37 | I8: 0.024647887 | J8: open
A9: 20251031-1-javadirect3 | B9: gemma3-12b | C9: direct | D9: 20251031-122752 | E9: 3 | F9: 4 | G9: 280 | H9: 37 | I9: 0.014084507 | J9: open
A10: 20251029-1-java-opensources | B10: gemma3-27b | C10: cascade | D10: 20251029-175440 | E10: 1 | F10: 8 | G10: 276 | H10: 40 | I10: 0.028169014 | J10: open
A11: 20251029-1-java-opensources | B11: gemma3-27b | C11: cascade | D11: 20251029-194639 | E11: 2 | F11: 9 | G11: 275 | H11: 36 | I11: 0.031690141 | J11: open
A12: 20251029-1-java-opensources | B12: gemma3-27b | C12: direct | D12: 20251030-043918 | E12: 1 | F12: 5 | G12: 279 | H12: 37 | I12: 0.017605634 | J12: open
A13: 20251029-1-java-opensources | B13: gemma3-27b | C13: direct | D13: 20251030-071615 | E13: 2 | F13: 13 | G13: 271 | H13: 53 | I13: 0.045774648 | J13: open
... A61: java-closesources | B61: gpt-5 | C61: direct | D61: 20251031-104145 | E61: 3 | F61: 130 | G61: 154 | H61: 256 | I61: 0.45774648 | J61: close

Sheet JavaScript Pivot
A3: 平均值项:score | C3: level | D3: mode
C4: 1 | E4: 2 | G4: 3 | H4: 总计
A5: source | B5: model | C5: cascade | D5: direct | E5: cascade | F5: direct | G5: direct
A6: close | B6: gemini-2.5-flash | C6: 0.077464789 | D6: 0.1443662 | E6: 0.15140845 | F6: 0.1584507 | G6: 0.31690141 | H6: 0.16971831
B7: gpt-3.5-turbo | C7: 0.024647887 | D7: 0.021126761 | E7: 0.024647887 | F7: 0.024647887 | G7: 0.038732394 | H7: 0.026760563
B8: gpt-5 | C8: 0.16197183 | D8: 0.23943662 | E8: 0.38380282 | F8: 0.3943662 | G8: 0.4471831 | H8: 0.32535211
A9: open | B9: codellama-13b | G9: 0.0035211268 | H9: 0.0035211268
B10: codellama-34b | G10: 0 | H10: 0
B11: deepseek-coder-33b | G11: 0.028169014 | H11: 0.028169014
B12: deepseek-coder-6.7b | G12: 0.021126761 | H12: 0.021126761
B13: gemma3-12b | C13: 0.035211268 | D13: 0.059859155 | E13: 0.01056338 | F13: 0 | G13: 0.13380282 | H13: 0.047887324
B14: gemma3-27b | C14: 0.070422535 | D14: 0.049295775 | E14: 0.035211268 | F14: 0.024647887 | G14: 0.14084507 | H14: 0.064084507
B15: gpt-oss-20b | C15: 0.056338028 | D15: 0.10915493 | E15: 0.073943662 | F15: 0.095070423 | G15: 0.080985915 | H15: 0.083098592
B16: llama3.1-8b | C16: 0.0035211268 | D16: 0 | E16: 0.021126761 | F16: 0.014084507 | G16: 0.0035211268 | H16: 0.0084507042
B17: llama3.3-70b | C17: 0.11267606 | D17: 0.13380282 | E17: 0.11619718 | F17: 0.20070423 | G17: 0.13380282 | H17: 0.13943662
B18: phi4-14b | C18: 0.052816901 | D18: 0.098591549 | E18: 0.080985915 | F18: 0.14084507 | G18: 0.11619718 | H18: 0.097887324
B19: qwen2.5-coder-14b | G19: 0.088028169 | H19: 0.088028169
B20: qwen2.5-coder-32b | G20: 0.095070423 | H20: 0.095070423
B21: qwen3-14b | C21: 0.052816901 | D21: 0.031690141 | E21: 0.038732394 | F21: 0.0070422535 | G21: 0.024647887 | H21: 0.030985915
B22: qwen3-30b | C22: 0.049295775 | D22: 0.028169014 | E22: 0.070422535 | F22: 0.059859155 | G22: 0.077464789 | H22: 0.057042254
A23: 总计 | C23: 0.063380282 | D23: 0.083226633 | E23: 0.091549296 | F23: 0.10179257 | G23: 0.10294118 | H23: 0.089990764

Sheet JavaScript
A1: date | B1: model | C1: mode | D1: timestamp | E1: level | F1: passed | G1: failed | H1: executed | I1: score | J1: source
A2: 20251028-1-jsdirect3 | B2: codellama-13b | C2: direct | D2: 20251029-033943 | E2: 3 | F2: 1 | G2: 283 | H2: 9 | I2: 0.0035211268 | J2: open
A3: 20251028-1-jsdirect3 | B3: codellama-34b | C3: direct | D3: 20251029-003016 | E3: 3 | F3: 0 | G3: 284 | H3: 0 | I3: 0 | J3: open
A4: 20251028-1-jsdirect3 | B4: deepseek-coder-33b | C4: direct | D4: 20251029-034434 | E4: 3 | F4: 8 | G4: 276 | H4: 50 | I4: 0.028169014 | J4: open
A5: 20251028-1-jsdirect3 | B5: deepseek-coder-6.7b | C5: direct | D5: 20251029-035859 | E5: 3 | F5: 6 | G5: 278 | H5: 72 | I5: 0.021126761 | J5: open
A6: 20251028-1-jsdirect3 | B6: qwen2.5-coder-14b | C6: direct | D6: 20251028-224242 | E6: 3 | F6: 25 | G6: 259 | H6: 133 | I6: 0.088028169 | J6: open
A7: 20251028-1-jsdirect3 | B7: qwen2.5-coder-32b | C7: direct | D7: 20251028-215453 | E7: 3 | F7: 27 | G7: 257 | H7: 153 | I7: 0.095070423 | J7: open
A8: 20251020-1 | B8: gemma3-12b | C8: cascade | D8: 20251020-214045 | E8: 1 | F8: 10 | G8: 274 | H8: 53 | I8: 0.035211268 | J8: open
A9: 20251020-1 | B9: gemma3-12b | C9: cascade | D9: 20251020-222603 | E9: 2 | F9: 3 | G9: 281 | H9: 20 | I9: 0.01056338 | J9: open
A10: 20251020-1 | B10: gemma3-12b | C10: direct | D10: 20251021-170829 | E10: 1 | F10: 17 | G10: 267 | H10: 51 | I10: 0.059859155 | J10: open
A11: 20251020-1 | B11: gemma3-12b | C11: direct | D11: 20251021-171901 | E11: 2 | F11: 0 | G11: 284 | H11: 0 | I11: 0 | J11: open
A12: 20251020-1 | B12: gemma3-27b | C12: cascade | D12: 20251020-234444 | E12: 1 | F12: 20 | G12: 264 | H12: 85 | I12: 0.070422535 | J12: open
A13: 20251020-1 | B13: gemma3-27b | C13: cascade | D13: 20251021-020650 | E13: 2 | F13: 10 | G13: 274 | H13: 62 | I13: 0.035211268 | J13: open
... A62: js-closesources | B62: gpt-5 | C62: direct | D62: 20251029-181051 | E62: 3 | F62: 127 | G62: 157 | H62: 231 | I62: 0.4471831 | J62: close
